Workbook

Sheet Instruction
A3: Instructions
B4: 1. Make a copy of the template
B5: 2. Overwrite the column A-C 'Investment Perf His' tab using your portfolio performance history(ideally >5 years)
B6: 3. Update 'Calculation results' tab following the instruction in the orange text box
B7: 4. Copy and paste table C5 to R25 into board paper.

Sheet Calculation results
S3: Accumulated return | V3: Annualised return | Y3: Volatility | Z3: Benchmark retunrs | AC3: Benchmark vol | AD3: Morningstar Category | AH3: Tracking error
E4: Fund vs BM. 5 year net returns. Fail if alpha<0 | F4: Fund vs peers. 5 year rank in Morningstar peer group. Fail if in 4th quartile | G4: Fund vs BM. 2 year net returns. Fail if alpha<0 | H4: Fund vs peers. 3 year rank in Morningstar peer group. Fail if in 4th quartile | I4: Annualised 2 year tracking error. Fail if >2x peer median TE | J4: Annualised 2 year volatility. Fail if >1.5x BM volatility | K4: Fail if <80% liquid in 21 business days | L4: Fail if not Approved/Investment Grade (Zenith, Lonsec), 3.5 (SQM) or Neutral (Morningstar) or higher | M4: Team (resourcing, skills, stability) | N4: Process (robust, disciplined, governance) | O4: Business (conflicts, support, stability) | P4: Product (viability, fees, capacity, concentration) | S4: 5 years | T4: 3 years | U4: 2 years | V4: 5 years | W4: 3 years | X4: 2 years | Y4: 2 years | Z4: 5 years | AA4: 3 years | AB4: 2 years | AC4: 2 years | AD4: 5 yr 4th Quartile Cut-off Return: | AE4: 3 yr 4th Quartile Cut-off Return: | AF4: 2 yr 4th Quartile Cut-off Return: | AG4: 2 yr Median tracking error: | AH4: 2 years Tracking error
D5: Overall Score (out of 100) | E5: 5yr Returns vs BM | F5: 5yr Rank vs Peers | G5: 3yr Returns vs BM | H5: 3yr Rank vs Peers | I5: Tracking Error | J5: Volatility | K5: Liquidity (Underlying) | L5: Ratings | M5: Team | N5: Process | O5: Business | P5: Product | R5: {=MAX(_xlfn._xlws.FILTER('Invert return series (5 years)'!B:B,'Invert return series (5 years)'!A:A='Calculation results'!C7))} -> 46022 | S5: =EDATE(R5,-60) -> 44196 | T5: =EDATE(R5,-36) -> 44926 | U5: =EDATE(R5,-24) -> 45291
E6: 0 | F6: 0 | G6: 0.2 | H6: 0.2 | I6: 0.05 | J6: 0.05 | K6: 0.1 | L6: 0.1 | M6: 0.1 | N6: 0.1 | O6: 0.05 | P6: 0.05 | Q6: Benchmark | R6: Morningstar Peer Group
C7: Aurora 0% Growth | D7: =SUMIF(E7:P7,CHAR(149),E$6:P$6) -> 0.9 | E7: =IF(V7>Z7,CHAR(149),"-") -> • | F7: =IF(V7>AD7,CHAR(149),"-") -> • | G7: =IF(W7>AA7,CHAR(149),"-") -> • | H7: =IF(W7>AE7,CHAR(149),"-") -> • | I7: =IF(AH7>2*AG7,"-",CHAR(149)) -> • | J7: =IF(Y7>1.5*AC7,"-",CHAR(149)) -> • | K7: • | L7: - | M7: • | N7: • | O7: • | P7: • | Q7: Morningstar AUS Con Tgt Alloc NR AUD | R7: Australia Fund Multisector Conservative | S7: {=PRODUCT(_xlfn._xlws.FILTER(1+'Invert return series (5 years)'!C$2:C$10000,('Invert return series (5 years)'!A$2:A$10000='Calculation results'!C7)*('Invert return series (5 years)'!B$2:B$10000>'Calculation results'!$S$5)*('Invert return series (5 years)'!B$2:B$10000<=$R$5)))} -> 1.1793661 | T7: {=PRODUCT(_xlfn._xlws.FILTER(1+'Invert return series (5 years)'!C$2:C$10000,('Invert return series (5 years)'!A$2:A$10000='Calculation results'!C7)*('Invert return series (5 years)'!B$2:B$10000>'Calculation results'!$T$5)*('Invert return series (5 years)'!B$2:B$10000<=$R$5)))} -> 1.1793661 | U7: {=PRODUCT(_xlfn._xlws.FILTER('Invert return series (5 years)'!C$2:C$10000+1,('Invert return series (5 years)'!A$2:A$10000='Calculation results'!C7)*('Invert return series (5 years)'!B$2:B$10000>'Calculation results'!$U$5)*('Invert return series (5 years)'!B$2:B$10000<=$R$5)))} -> 1.104915 | V7: =(PRODUCT(S7)^(0.2)-1) -> 0.033545802 | W7: =PRODUCT(T7)^(0.333333333)-1 -> 0.056532544 | X7: =(PRODUCT(U7)^(0.5)-1) -> 0.051149375 | Y7: {=STDEV(_xlfn._xlws.FILTER('Invert return series (5 years)'!C$2:C$1000+1,('Invert return series (5 years)'!A$2:A$1000='Calculation results'!C7)*('Invert return series (5 years)'!B$2:B$1000>'Calculation results'!$U$5)*('Invert return series (5 years)'!B$2:B$1000<=$R$5)))*SQRT(12)} -> 0.019056829 | Z7: {=_xlfn._xlws.FILTER('BM Data'!$B$7:$B$1000,'BM Data'!$A$7:$A$1000=Q7)/100} -> 0.01405189 | AA7: {=_xlfn._xlws.FILTER('BM Data'!$D$7:$D$1000,'BM Data'!$A$7:$A$1000=$Q7)/100} -> 0.04702102 | AB7: {=_xlfn._xlws.FILTER('BM Data'!$F$7:$F$1000,'BM Data'!$A$7:$A$1000=$Q7)/100} -> 0.04247839 | AC7: {=_xlfn._xlws.FILTER('BM Data'!G$7:G$1000,'BM Data'!$A$7:$A$1000=$Q7)/100} -> 0.02447929 | AD7: =VLOOKUP($R7,'Morningstar Category Data'!$A:$E,5,FALSE)/100 -> 0.02067251 | AE7: =VLOOKUP($R7,'Morningstar Category Data'!$A:$E,4,FALSE)/100 -> 0.05191326 | AF7: =VLOOKUP($R7,'Morningstar Category Data'!$A:$E,3,FALSE)/100 -> 0.04974302 | AG7: =VLOOKUP($R7,'Morningstar Category Data'!$I:$J,2,FALSE)/100 -> 0.01228132 | AH7: {=STDEV( _xlfn._xlws.FILTER( 'Invert return series (5 years)'!C$2:C$1000, ('Invert return series (5 years)'!A$2:A$1000='Calculation results'!C7) *('Invert return series (5 years)'!B$2:B$1000>'Calculation results'!$U$5)*('Invert return series (5 years)'!B$2:B$1000<=$R$5) ) - TRANSPOSE( _xlfn._xlws.FILTER( INDEX('BM Data'!$K$8:$BE$500, MATCH(Q7, 'BM Data'!$A$8:$A$500, 0), ), INDEX('BM Data'!$K$8:$BE$500, MATCH(Q7, 'BM Data'!$A$8:$A$500, 0), ) <> "" ))/100 )*SQRT(12)} -> 0.0090903348
C8: Aurora 100% Growth Portfolio | D8: =SUMIF(E8:P8,CHAR(149),E$6:P$6) -> 0.9 | E8: =IF(V8>Z8,CHAR(149),"-") -> - | F8: =IF(V8>AD8,CHAR(149),"-") -> • | G8: =IF(W8>AA8,CHAR(149),"-") -> • | H8: =IF(W8>AE8,CHAR(149),"-") -> • | I8: =IF(AH8>2*AG8,"-",CHAR(149)) -> • | J8: =IF(Y8>1.5*AC8,"-",CHAR(149)) -> • | K8: • | L8: - | M8: • | N8: • | O8: • | P8: • | Q8: Morningstar AUS Agg Tgt Alloc NR AUD | R8: Australia Fund Multisector Aggressive | S8: {=PRODUCT(_xlfn._xlws.FILTER(1+'Invert return series (5 years)'!C$2:C$10000,('Invert return series (5 years)'!A$2:A$10000='Calculation results'!C8)*('Invert return series (5 years)'!B$2:B$10000>'Calculation results'!$S$5)*('Invert return series (5 years)'!B$2:B$10000<=$R$5)))} -> 1.5828326 | T8: {=PRODUCT(_xlfn._xlws.FILTER(1+'Invert return series (5 years)'!C$2:C$10000,('Invert return series (5 years)'!A$2:A$10000='Calculation results'!C8)*('Invert return series (5 years)'!B$2:B$10000>'Calculation results'!$T$5)*('Invert return series (5 years)'!B$2:B$10000<=$R$5)))} -> 1.5828326 | U8: {=PRODUCT(_xlfn._xlws.FILTER('Invert return series (5 years)'!C$2:C$10000+1,('Invert return series (5 years)'!A$2:A$10000='Calculation results'!C8)*('Invert return series (5 years)'!B$2:B$10000>'Calculation results'!$U$5)*('Invert return series (5 years)'!B$2:B$10000<=$R$5)))} -> 1.369041 | V8: =(PRODUCT(S8)^(0.2)-1) -> 0.096192938 | W8: =PRODUCT(T8)^(0.33333)-1 -> 0.16540712 | X8: =(PRODUCT(U8)^(0.5)-1) -> 0.17006027 | Y8: {=STDEV(_xlfn._xlws.FILTER('Invert return series (5 years)'!C$2:C$1000+1,('Invert return series (5 years)'!A$2:A$1000='Calculation results'!C8)*('Invert return series (5 years)'!B$2:B$1000>'Calculation results'!$U$5)*('Invert return series (5 years)'!B$2:B$1000<=$R$5)))*SQRT(12)} -> 0.072349173 | Z8: {=_xlfn._xlws.FILTER('BM Data'!$B$7:$B$1000,'BM Data'!$A$7:$A$1000=Q8)/100} -> 0.10446274 | AA8: {=_xlfn._xlws.FILTER('BM Data'!$D$7:$D$1000,'BM Data'!$A$7:$A$1000=$Q8)/100} -> 0.14801448 | AB8: {=_xlfn._xlws.FILTER('BM Data'!$F$7:$F$1000,'BM Data'!$A$7:$A$1000=$Q8)/100} -> 0.14472671 | AC8: {=_xlfn._xlws.FILTER('BM Data'!G$7:G$1000,'BM Data'!$A$7:$A$1000=$Q8)/100} -> 0.0688133 | AD8: =VLOOKUP($R8,'Morningstar Category Data'!$A:$E,5,FALSE)/100 -> 0.08647114 | AE8: =VLOOKUP($R8,'Morningstar Category Data'!$A:$E,4,FALSE)/100 -> 0.12524835 | AF8: =VLOOKUP($R8,'Morningstar Category Data'!$A:$E,3,FALSE)/100 -> 0.12081514 | AG8: =VLOOKUP($R8,'Morningstar Category Data'!$I:$J,2,FALSE)/100 -> 0.0159729 | AH8: {=STDEV( _xlfn._xlws.FILTER( 'Invert return series (5 years)'!C$2:C$1000, ('Invert return series (5 years)'!A$2:A$1000='Calculation results'!C8) *('Invert return series (5 years)'!B$2:B$1000>'Calculation results'!$U$5)*('Invert return series (5 years)'!B$2:B$1000<=$R$5) ) - TRANSPOSE( _xlfn._xlws.FILTER( INDEX('BM Data'!$K$8:$BE$500, MATCH(Q8, 'BM Data'!$A$8:$A$500, 0), ), INDEX('BM Data'!$K$8:$BE$500, MATCH(Q8, 'BM Data'!$A$8:$A$500, 0), ) <> "" ))/100 )*SQRT(12)} -> 0.022565865
D10: Green > 60%
D11: Amber 50-59% | K11: • | L11: Pass
D12: Red < 50% | K12: – | L12: Fail
C13: Please note:
C14: Managed Portfolio scoring weights are defined in Investment Options Charter and Operational Guidelines October 2021.
C16: * Where portfolio's have an absolute return target tracking error score cannot be calculated. In these cases the Volatiliy weight doubles and increases from 5% to 10%
C17: ^ For portfolio's that do not have 5 yr track record the performance weighting of 2/3 years doubles from 10% to 20%.

Sheet Investment Perf His
A1: Portfolio Name | B1: Date | C1: Paste series below
A2: Aurora 0% Growth | B2: 44957 | C2: 0.02288292
A3: Aurora 0% Growth | B3: 44985 | C3: -0.00757107
A4: Aurora 0% Growth | B4: 45016 | C4: 0.01473816
A5: Aurora 0% Growth | B5: 45046 | C5: 0.00401853
A6: Aurora 0% Growth | B6: 45077 | C6: -0.00638449
A7: Aurora 0% Growth | B7: 45107 | C7: -0.00957917
A8: Aurora 0% Growth | B8: 45138 | C8: 0.00607261
A9: Aurora 0% Growth | B9: 45169 | C9: 0.00695855
A10: Aurora 0% Growth | B10: 45199 | C10: -0.00606397
A11: Aurora 0% Growth | B11: 45230 | C11: -0.00674147
A12: Aurora 0% Growth | B12: 45260 | C12: 0.02266398
A13: Aurora 0% Growth | B13: 45291 | C13: 0.02533541
... A73: Aurora 100% Growth Portfolio | B73: 46022 | C73: -0.00248887

Sheet Invert return series (5 years)
A1: Portfolio Name | B1: Date | C1: Paste series below | D1: Corrected order (most recent month at top)
A2: {=_xlfn.SORTBY('Investment Perf His'!A2:C8852,'Investment Perf His'!A2:A8852,1,'Investment Perf His'!B2:B8852,1)} -> Aurora 0% Growth | B2: 44957 | C2: 0.02288292
A3: Aurora 0% Growth | B3: 44985 | C3: -0.00757107
A4: Aurora 0% Growth | B4: 45016 | C4: 0.01473816
A5: Aurora 0% Growth | B5: 45046 | C5: 0.00401853
A6: Aurora 0% Growth | B6: 45077 | C6: -0.00638449
A7: Aurora 0% Growth | B7: 45107 | C7: -0.00957917
A8: Aurora 0% Growth | B8: 45138 | C8: 0.00607261
A9: Aurora 0% Growth | B9: 45169 | C9: 0.00695855
A10: Aurora 0% Growth | B10: 45199 | C10: -0.00606397
A11: Aurora 0% Growth | B11: 45230 | C11: -0.00674147
A12: Aurora 0% Growth | B12: 45260 | C12: 0.02266398 | H12: =_xlfn.STDEV.S(C14:C37)*SQRT(12) -> 0.019056829
A13: Aurora 0% Growth | B13: 45291 | C13: 0.02533541
A14: Aurora 0% Growth | B14: 45322 | C14: 0.00305986
A15: Aurora 0% Growth | B15: 45351 | C15: -0.00025378
A16: Aurora 0% Growth | B16: 45382 | C16: 0.01093866
A17: Aurora 0% Growth | B17: 45412 | C17: -0.00920594
A18: Aurora 0% Growth | B18: 45443 | C18: 0.00553179
A19: Aurora 0% Growth | B19: 45473 | C19: 0.00628667
A20: Aurora 0% Growth | B20: 45504 | C20: 0.01481509
A21: Aurora 0% Growth | B21: 45535 | C21: 0.0087324
A22: Aurora 0% Growth | B22: 45565 | C22: 0.00661086
A23: Aurora 0% Growth | B23: 45596 | C23: -0.00775096
A24: Aurora 0% Growth | B24: 45626 | C24: 0.00995131
... A73: Aurora 100% Growth Portfolio | B73: 46022 | C73: -0.00248887
A74: 0 | B74: 0 | C74: 0
A75: 0 | B75: 0 | C75: 0
A76: 0 | B76: 0 | C76: 0
A77: 0 | B77: 0 | C77: 0
A78: 0 | B78: 0 | C78: 0
A79: 0 | B79: 0 | C79: 0
A80: 0 | B80: 0 | C80: 0
A81: 0 | B81: 0 | C81: 0
A82: 0 | B82: 0 | C82: 0
A83: 0 | B83: 0 | C83: 0
A84: 0 | B84: 0 | C84: 0
A85: 0 | B85: 0 | C85: 0
... A8852: 0 | B8852: 0 | C8852: 0

Sheet Invert return series (3 years)
A1: Paste series below | B1: Corrected order (most recent month at top)
A2: -0.011368317 | B2: =A37 -> -0.019161857
A3: -0.00083905231 | B3: =A36 -> -0.009174655
A4: 0.011113253 | B4: =A35 -> -0.030244762
A5: -0.0037259254 | B5: =A34 -> 0.032136723
A6: 0.018776878 | B6: =A33 -> -0.016170345
A7: -0.0050125762 | B7: =A32 -> -0.032049431
A8: 0.0083382064 | B8: =A31 -> 0.020472374
A9: 0.0076003792 | B9: =A30 -> 0.023159597
A10: 0.01734194 | B10: =A29 -> -0.019686065
A11: 0.0087494403 | B11: =A28 -> 0.028205909
A12: 0.010123351 | B12: =A27 -> -0.0080229702
A13: -0.016858346 | B13: =A26 -> 0.015557598
A14: 0.015097839 | B14: =A25 -> 0.0087650403
A15: 0.0091940259 | B15: =A24 -> -0.0039882307
A16: 0.0072424781 | B16: =A23 -> 0.0049977342
A17: 0.027364197 | B17: =A22 -> 0.0085679419
A18: 0.032476107 | B18: =A21 -> 0.00099608678
A19: -0.01231937 | B19: =A20 -> -0.01773787
A20: -0.01773787 | B20: =A19 -> -0.01231937
A21: 0.00099608678 | B21: =A18 -> 0.032476107
A22: 0.0085679419 | B22: =A17 -> 0.027364197
A23: 0.0049977342 | B23: =A16 -> 0.0072424781
A24: -0.0039882307 | B24: =A15 -> 0.0091940259
A25: 0.0087650403 | B25: =A14 -> 0.015097839
A26: 0.015557598 | B26: =A13 -> -0.016858346
A27: -0.0080229702 | B27: =A12 -> 0.010123351
A28: 0.028205909 | B28: =A11 -> 0.0087494403
A29: -0.019686065 | B29: =A10 -> 0.01734194
A30: 0.023159597 | B30: =A9 -> 0.0076003792
A31: 0.020472374 | B31: =A8 -> 0.0083382064
A32: -0.032049431 | B32: =A7 -> -0.0050125762
A33: -0.016170345 | B33: =A6 -> 0.018776878
A34: 0.032136723 | B34: =A5 -> -0.0037259254
A35: -0.030244762 | B35: =A4 -> 0.011113253
A36: -0.009174655 | B36: =A3 -> -0.00083905231
A37: -0.019161857 | B37: =A2 -> -0.011368317

Sheet Invert return series (2 years)
A1: Paste series below | B1: Corrected order (most recent month at top)
A2: 0.03070665 | B2: =A25 -> 0.001265213
A3: -0.057978741 | B3: =A24 -> -0.0011540287
A4: 0.049354245 | B4: =A23 -> 0.036626656
A5: 0.005765681 | B5: =A22 -> 0.025042679
A6: -0.026776591 | B6: =A21 -> 0.041179419
A7: 0.018036866 | B7: =A20 -> 0.041752524
A8: 0.02051514 | B8: =A19 -> 0.015407347
A9: 0.017416475 | B9: =A18 -> -0.0088147818
A10: 0.034338148 | B10: =A17 -> 0.046012452
A11: 0.00093871301 | B11: =A16 -> 0.035364225
A12: -0.01603754 | B12: =A15 -> -0.0063277413
A13: -0.10878218 | B13: =A14 -> 0.0204754
A14: 0.0204754 | B14: =A13 -> -0.10878218
A15: -0.0063277413 | B15: =A12 -> -0.01603754
A16: 0.035364225 | B16: =A11 -> 0.00093871301
A17: 0.046012452 | B17: =A10 -> 0.034338148
A18: -0.0088147818 | B18: =A9 -> 0.017416475
A19: 0.015407347 | B19: =A8 -> 0.02051514
A20: 0.041752524 | B20: =A7 -> 0.018036866
A21: 0.041179419 | B21: =A6 -> -0.026776591
A22: 0.025042679 | B22: =A5 -> 0.005765681
A23: 0.036626656 | B23: =A4 -> 0.049354245
A24: -0.0011540287 | B24: =A3 -> -0.057978741
A25: 0.001265213 | B25: =A2 -> 0.03070665

Sheet Manual Calc (5 years)
B1: Return Series | D1: Investment Option | F1: Investment option monthly returns> | G1: Month 1 | I1: Month 2 | K1: Month 3 | M1: Month 4 | O1: Month 5 | Q1: Month 6 | S1: Month 7 | U1: Month 8 | W1: Month 9 | Y1: Month 10 | AA1: Month 11 | AC1: Month 12 | AE1: Month 13 | AG1: Month 14 | AI1: Month 15 | AK1: Month 16 | AM1: Month 17 | AO1: Month 18 | AQ1: Month 19 | AS1: Month 20 | AU1: Month 21 | AW1: Month 22 | AY1: Month 23 | BA1: Month 24
A2: Month 60 | B2: ='Invert return series (5 years)'!$D2 -> 0 | C2: =(1+B2) -> 1 | D2: 5 yr annualised return: | E2: {=(PRODUCT(1+$B$2:$B$61)^(0.2)-1)*100} -> 0 | G2: =$B25*100 -> 0 | I2: =$B24*100 -> 0 | K2: =$B23*100 -> 0 | M2: =$B22*100 -> 0 | O2: =$B21*100 -> 0 | Q2: =$B20*100 -> 0 | S2: =$B19*100 -> 0 | U2: =$B18*100 -> 0 | W2: =$B17*100 -> 0 | Y2: =$B16*100 -> 0 | AA2: =$B15*100 -> 0 | AC2: =$B14*100 -> 0 | AE2: =$B13*100 -> 0 | AG2: =$B12*100 -> 0 | AI2: =$B11*100 -> 0 | AK2: =$B10*100 -> 0 | AM2: =$B9*100 -> 0 | AO2: =$B8*100 -> 0 | AQ2: =$B7*100 -> 0 | AS2: =$B6*100 -> 0 | AU2: =$B5*100 -> 0 | AW2: =$B4*100 -> 0 | AY2: =$B3*100 -> 0 | BA2: =$B2*100 -> 0
A3: Month 59 | B3: ='Invert return series (5 years)'!$D3 -> 0 | C3: =(1+B3) -> 1 | D3: 3 yr annualised return: | E3: {=(PRODUCT(1+$B$2:$B$37)^(0.333333333)-1)*100} -> 0 | F3: Benchmark monthly returns> | G3: =INDEX('BM Data'!$K$7:$BE$260,MATCH('Manual Calc (5 years)'!$F7,'BM Data'!$A$7:$A$260,0),MATCH('Manual Calc (5 years)'!G$1,'BM Data'!$K$1:$BE$1,0)) -> 0.97442 | I3: =INDEX('BM Data'!$K$7:$BE$260,MATCH('Manual Calc (5 years)'!$F7,'BM Data'!$A$7:$A$260,0),MATCH('Manual Calc (5 years)'!I$1,'BM Data'!$K$1:$BE$1,0)) -> 1.46685 | K3: =INDEX('BM Data'!$K$7:$BE$260,MATCH('Manual Calc (5 years)'!$F7,'BM Data'!$A$7:$A$260,0),MATCH('Manual Calc (5 years)'!K$1,'BM Data'!$K$1:$BE$1,0)) -> 2.01317 | M3: =INDEX('BM Data'!$K$7:$BE$260,MATCH('Manual Calc (5 years)'!$F7,'BM Data'!$A$7:$A$260,0),MATCH('Manual Calc (5 years)'!M$1,'BM Data'!$K$1:$BE$1,0)) -> -2.38612 | O3: =INDEX('BM Data'!$K$7:$BE$260,MATCH('Manual Calc (5 years)'!$F7,'BM Data'!$A$7:$A$260,0),MATCH('Manual Calc (5 years)'!O$1,'BM Data'!$K$1:$BE$1,0)) -> 1.09816 | Q3: =INDEX('BM Data'!$K$7:$BE$260,MATCH('Manual Calc (5 years)'!$F7,'BM Data'!$A$7:$A$260,0),MATCH('Manual Calc (5 years)'!Q$1,'BM Data'!$K$1:$BE$1,0)) -> 0.99444 | S3: =INDEX('BM Data'!$K$7:$BE$260,MATCH('Manual Calc (5 years)'!$F7,'BM Data'!$A$7:$A$260,0),MATCH('Manual Calc (5 years)'!S$1,'BM Data'!$K$1:$BE$1,0)) -> 2.71493 | U3: =INDEX('BM Data'!$K$7:$BE$260,MATCH('Manual Calc (5 years)'!$F7,'BM Data'!$A$7:$A$260,0),MATCH('Manual Calc (5 years)'!U$1,'BM Data'!$K$1:$BE$1,0)) -> 0.66696 | W3: =INDEX('BM Data'!$K$7:$BE$260,MATCH('Manual Calc (5 years)'!$F7,'BM Data'!$A$7:$A$260,0),MATCH('Manual Calc (5 years)'!W$1,'BM Data'!$K$1:$BE$1,0)) -> 1.18405 | Y3: =INDEX('BM Data'!$K$7:$BE$260,MATCH('Manual Calc (5 years)'!$F7,'BM Data'!$A$7:$A$260,0),MATCH('Manual Calc (5 years)'!Y$1,'BM Data'!$K$1:$BE$1,0)) -> -0.67899 | AA3: =INDEX('BM Data'!$K$7:$BE$260,MATCH('Manual Calc (5 years)'!$F7,'BM Data'!$A$7:$A$260,0),MATCH('Manual Calc (5 years)'!AA$1,'BM Data'!$K$1:$BE$1,0)) -> 2.41574 | AC3: =INDEX('BM Data'!$K$7:$BE$260,MATCH('Manual Calc (5 years)'!$F7,'BM Data'!$A$7:$A$260,0),MATCH('Manual Calc (5 years)'!AC$1,'BM Data'!$K$1:$BE$1,0)) -> -0.67086 | AE3: =INDEX('BM Data'!$K$7:$BE$260,MATCH('Manual Calc (5 years)'!$F7,'BM Data'!$A$7:$A$260,0),MATCH('Manual Calc (5 years)'!AE$1,'BM Data'!$K$1:$BE$1,0)) -> 1.87484 | AG3: =INDEX('BM Data'!$K$7:$BE$260,MATCH('Manual Calc (5 years)'!$F7,'BM Data'!$A$7:$A$260,0),MATCH('Manual Calc (5 years)'!AG$1,'BM Data'!$K$1:$BE$1,0)) -> -0.37671 | AI3: =INDEX('BM Data'!$K$7:$BE$260,MATCH('Manual Calc (5 years)'!$F7,'BM Data'!$A$7:$A$260,0),MATCH('Manual Calc (5 years)'!AI$1,'BM Data'!$K$1:$BE$1,0)) -> -1.78595 | AK3: =INDEX('BM Data'!$K$7:$BE$260,MATCH('Manual Calc (5 years)'!$F7,'BM Data'!$A$7:$A$260,0),MATCH('Manual Calc (5 years)'!AK$1,'BM Data'!$K$1:$BE$1,0)) -> 1.08211 | AM3: =INDEX('BM Data'!$K$7:$BE$260,MATCH('Manual Calc (5 years)'!$F7,'BM Data'!$A$7:$A$260,0),MATCH('Manual Calc (5 years)'!AM$1,'BM Data'!$K$1:$BE$1,0)) -> 2.20645 | AO3: =INDEX('BM Data'!$K$7:$BE$260,MATCH('Manual Calc (5 years)'!$F7,'BM Data'!$A$7:$A$260,0),MATCH('Manual Calc (5 years)'!AO$1,'BM Data'!$K$1:$BE$1,0)) -> 1.40935 | AQ3: =INDEX('BM Data'!$K$7:$BE$260,MATCH('Manual Calc (5 years)'!$F7,'BM Data'!$A$7:$A$260,0),MATCH('Manual Calc (5 years)'!AQ$1,'BM Data'!$K$1:$BE$1,0)) -> 1.21245 | AS3: =INDEX('BM Data'!$K$7:$BE$260,MATCH('Manual Calc (5 years)'!$F7,'BM Data'!$A$7:$A$260,0),MATCH('Manual Calc (5 years)'!AS$1,'BM Data'!$K$1:$BE$1,0)) -> 1.42229 | AU3: =INDEX('BM Data'!$K$7:$BE$260,MATCH('Manual Calc (5 years)'!$F7,'BM Data'!$A$7:$A$260,0),MATCH('Manual Calc (5 years)'!AU$1,'BM Data'!$K$1:$BE$1,0)) -> 0.66659 | AW3: =INDEX('BM Data'!$K$7:$BE$260,MATCH('Manual Calc (5 years)'!$F7,'BM Data'!$A$7:$A$260,0),MATCH('Manual Calc (5 years)'!AW$1,'BM Data'!$K$1:$BE$1,0)) -> 1.18844 | AY3: =INDEX('BM Data'!$K$7:$BE$260,MATCH('Manual Calc (5 years)'!$F7,'BM Data'!$A$7:$A$260,0),MATCH('Manual Calc (5 years)'!AY$1,'BM Data'!$K$1:$BE$1,0)) -> -0.60468 | BA3: =INDEX('BM Data'!$K$7:$BE$260,MATCH('Manual Calc (5 years)'!$F7,'BM Data'!$A$7:$A$260,0),MATCH('Manual Calc (5 years)'!BA$1,'BM Data'!$K$1:$BE$1,0)) -> 0.05682
A4: Month 58 | B4: ='Invert return series (5 years)'!$D4 -> 0 | C4: =(1+B4) -> 1 | D4: 2 yr annualised vol: | E4: =(STDEV($B$2:$B$25)*SQRT(12))*100 -> 0 | F4: Monthly Excess> | G4: =G2-G3 -> -0.97442 | I4: =I2-I3 -> -1.46685 | K4: =K2-K3 -> -2.01317 | M4: =M2-M3 -> 2.38612 | O4: =O2-O3 -> -1.09816 | Q4: =Q2-Q3 -> -0.99444 | S4: =S2-S3 -> -2.71493 | U4: =U2-U3 -> -0.66696 | W4: =W2-W3 -> -1.18405 | Y4: =Y2-Y3 -> 0.67899 | AA4: =AA2-AA3 -> -2.41574 | AC4: =AC2-AC3 -> 0.67086 | AE4: =AE2-AE3 -> -1.87484 | AG4: =AG2-AG3 -> 0.37671 | AI4: =AI2-AI3 -> 1.78595 | AK4: =AK2-AK3 -> -1.08211 | AM4: =AM2-AM3 -> -2.20645 | AO4: =AO2-AO3 -> -1.40935 | AQ4: =AQ2-AQ3 -> -1.21245 | AS4: =AS2-AS3 -> -1.42229 | AU4: =AU2-AU3 -> -0.66659 | AW4: =AW2-AW3 -> -1.18844 | AY4: =AY2-AY3 -> 0.60468 | BA4: =BA2-BA3 -> -0.05682
A5: Month 57 | B5: ='Invert return series (5 years)'!$D5 -> 0 | C5: =(1+B5) -> 1 | F5: Tracking error | G5: =STDEV(G4,I4,K4,M4,O4,Q4,S4,U4,W4,Y4,AA4,AC4,AE4,AG4,AI4,AK4,AM4,AO4,AQ4,AS4,AU4,AW4,AY4,BA4)*SQRT(12) -> 4.4455966
A6: Month 56 | B6: ='Invert return series (5 years)'!$D6 -> 0 | C6: =(1+B6) -> 1
A7: Month 55 | B7: ='Invert return series (5 years)'!$D7 -> 0 | C7: =(1+B7) -> 1 | D7: Benchmark: | F7: Morningstar AUS Balance Tgt Alloc NR AUD
A8: Month 54 | B8: ='Invert return series (5 years)'!$D8 -> 0 | C8: =(1+B8) -> 1 | D8: 5 yr annualised return: | E8: =VLOOKUP($F$7,'BM Data'!$A:$G,2,FALSE) -> 5.607414
A9: Month 53 | B9: ='Invert return series (5 years)'!$D9 -> 0 | C9: =(1+B9) -> 1 | D9: 3 yr annualised return: | E9: =VLOOKUP($F$7,'BM Data'!$A:$G,4,FALSE) -> 9.72249
A10: Month 52 | B10: ='Invert return series (5 years)'!$D10 -> 0 | C10: =(1+B10) -> 1 | D10: 2 yr annualised vol: | E10: =VLOOKUP($F$7,'BM Data'!$A:$G,7,FALSE) -> 4.445597
A11: Month 51 | B11: ='Invert return series (5 years)'!$D11 -> 0 | C11: =(1+B11) -> 1
A12: Month 50 | B12: ='Invert return series (5 years)'!$D12 -> 0 | C12: =(1+B12) -> 1
A13: Month 49 | B13: ='Invert return series (5 years)'!$D13 -> 0 | C13: =(1+B13) -> 1 | D13: Morningstar Category: | F13: Australia Fund Multisector Balanced
A14: Month 48 | B14: ='Invert return series (5 years)'!$D14 -> 0 | C14: =(1+B14) -> 1 | D14: 5 yr 4th Quartile Cut-off Return: | E14: =VLOOKUP($F$13,'Morningstar Category Data'!$A:$E,5,FALSE) -> 5.229288
A15: Month 47 | B15: ='Invert return series (5 years)'!$D15 -> 0 | C15: =(1+B15) -> 1 | D15: 3 yr 4th Quartile Cut-off Return: | E15: =VLOOKUP($F$13,'Morningstar Category Data'!$A:$E,4,FALSE) -> 8.046388
A16: Month 46 | B16: ='Invert return series (5 years)'!$D16 -> 0 | C16: =(1+B16) -> 1 | D16: 2 yr Median tracking error: | E16: =VLOOKUP($F$13,'Morningstar Category Data'!$I:$J,2,FALSE) -> 1.139196
A17: Month 45 | B17: ='Invert return series (5 years)'!$D17 -> 0 | C17: =(1+B17) -> 1
A18: Month 44 | B18: ='Invert return series (5 years)'!$D18 -> 0 | C18: =(1+B18) -> 1
A19: Month 43 | B19: ='Invert return series (5 years)'!$D19 -> 0 | C19: =(1+B19) -> 1
A20: Month 42 | B20: ='Invert return series (5 years)'!$D20 -> 0 | C20: =(1+B20) -> 1
A21: Month 41 | B21: ='Invert return series (5 years)'!$D21 -> 0 | C21: =(1+B21) -> 1
A22: Month 40 | B22: ='Invert return series (5 years)'!$D22 -> 0 | C22: =(1+B22) -> 1
A23: Month 39 | B23: ='Invert return series (5 years)'!$D23 -> 0 | C23: =(1+B23) -> 1
A24: Month 38 | B24: ='Invert return series (5 years)'!$D24 -> 0 | C24: =(1+B24) -> 1
A25: Month 37 | B25: ='Invert return series (5 years)'!$D25 -> 0 | C25: =(1+B25) -> 1
A26: Month 36 | B26: ='Invert return series (5 years)'!$D26 -> 0 | C26: =(1+B26) -> 1
A27: Month 35 | B27: ='Invert return series (5 years)'!$D27 -> 0 | C27: =(1+B27) -> 1
A28: Month 34 | B28: ='Invert return series (5 years)'!$D28 -> 0 | C28: =(1+B28) -> 1
... A61: Month 1 | B61: ='Invert return series (5 years)'!$D61 -> 0 | C61: =(1+B61) -> 1
A64: Scoring Summary
A65: Fund vs BM. 5 year net returns. Fail if alpha<0 | B65: Fund vs peers. 5 year rank in Morningstar peer group. Fail if in 4th quartile | C65: Fund vs BM. 3 year net returns. Fail if alpha<0 | D65: Fund vs peers. 3 year rank in Morningstar peer group. Fail if in 4th quartile | E65: Annualised 2 year tracking error. Fail if >2x peer median TE | F65: Annualised 2 year volatility. Fail if >1.5x BM volatility | G65: Fail if <80% liquid in 21 business days | H65: Fail if not Approved/Investment Grade (Zenith, Lonsec), 3.5 (SQM) or Neutral (Morningstar) or higher | I65: Team (resourcing, skills, stability) | J65: Process (robust, disciplined, governance) | K65: Business (conflicts, support, stability) | L65: Product (viability, fees, capacity, concentration) | M65: Score | N65: Final Rating
A66: =IF(E2>E8,10,"-") -> - | B66: =IF(E2>E14,10,"-") -> - | C66: =IF(E3>E9,10,"-") -> - | D66: =IF(E3>E15,10,"-") -> - | E66: =IF(G5>(2*E16),"-",5) -> - | F66: =IF(E4>(1.5*E10),"-",5) -> 5 | G66: 10 | I66: 10 | J66: 10 | K66: 5 | L66: 5 | M66: =SUM(A66:L66) -> 45 | N66: =IF(M66<50,"Red",IF(M66>60,"Green","Amber")) -> Red

Sheet Manual Calc (3 years)
B1: Return Series | D1: Investment Option | F1: Investment option monthly returns> | G1: Month 1 | I1: Month 2 | K1: Month 3 | M1: Month 4 | O1: Month 5 | Q1: Month 6 | S1: Month 7 | U1: Month 8 | W1: Month 9 | Y1: Month 10 | AA1: Month 11 | AC1: Month 12 | AE1: Month 13 | AG1: Month 14 | AI1: Month 15 | AK1: Month 16 | AM1: Month 17 | AO1: Month 18 | AQ1: Month 19 | AS1: Month 20 | AU1: Month 21 | AW1: Month 22 | AY1: Month 23 | BA1: Month 24
A2: Month 36 | B2: ='Invert return series (3 years)'!$B2 -> -0.019161857 | D2: 3 yr annualised return: | E2: {=(PRODUCT(1+$B$2:$B$37)^(0.333333333)-1)*100} -> 3.5512209 | G2: =$B25*100 -> 1.5097839 | I2: =$B24*100 -> 0.91940259 | K2: =$B23*100 -> 0.72424781 | M2: =$B22*100 -> 2.7364197 | O2: =$B21*100 -> 3.2476107 | Q2: =$B20*100 -> -1.231937 | S2: =$B19*100 -> -1.773787 | U2: =$B18*100 -> 0.099608678 | W2: =$B17*100 -> 0.85679419 | Y2: =$B16*100 -> 0.49977342 | AA2: =$B15*100 -> -0.39882307 | AC2: =$B14*100 -> 0.87650403 | AE2: =$B13*100 -> 1.5557598 | AG2: =$B12*100 -> -0.80229702 | AI2: =$B11*100 -> 2.8205909 | AK2: =$B10*100 -> -1.9686065 | AM2: =$B9*100 -> 2.3159597 | AO2: =$B8*100 -> 2.0472374 | AQ2: =$B7*100 -> -3.2049431 | AS2: =$B6*100 -> -1.6170345 | AU2: =$B5*100 -> 3.2136723 | AW2: =$B4*100 -> -3.0244762 | AY2: =$B3*100 -> -0.9174655 | BA2: =$B2*100 -> -1.9161857
A3: Month 35 | B3: ='Invert return series (3 years)'!$B3 -> -0.009174655 | D3: 2 yr annualised vol: | E3: =(STDEV($B$2:$B$25)*SQRT(12))*100 -> 6.768104 | F3: Benchmark monthly returns> | G3: =INDEX('BM Data'!$K$7:$BE$260,MATCH('Manual Calc (3 years)'!$F7,'BM Data'!$A$7:$A$260,0),MATCH('Manual Calc (3 years)'!G$1,'BM Data'!$K$1:$BE$1,0)) -> 0.59675 | I3: =INDEX('BM Data'!$K$7:$BE$260,MATCH('Manual Calc (3 years)'!$F7,'BM Data'!$A$7:$A$260,0),MATCH('Manual Calc (3 years)'!I$1,'BM Data'!$K$1:$BE$1,0)) -> 0.67652 | K3: =INDEX('BM Data'!$K$7:$BE$260,MATCH('Manual Calc (3 years)'!$F7,'BM Data'!$A$7:$A$260,0),MATCH('Manual Calc (3 years)'!K$1,'BM Data'!$K$1:$BE$1,0)) -> 1.58729 | M3: =INDEX('BM Data'!$K$7:$BE$260,MATCH('Manual Calc (3 years)'!$F7,'BM Data'!$A$7:$A$260,0),MATCH('Manual Calc (3 years)'!M$1,'BM Data'!$K$1:$BE$1,0)) -> -2.0119 | O3: =INDEX('BM Data'!$K$7:$BE$260,MATCH('Manual Calc (3 years)'!$F7,'BM Data'!$A$7:$A$260,0),MATCH('Manual Calc (3 years)'!O$1,'BM Data'!$K$1:$BE$1,0)) -> 0.81376 | Q3: =INDEX('BM Data'!$K$7:$BE$260,MATCH('Manual Calc (3 years)'!$F7,'BM Data'!$A$7:$A$260,0),MATCH('Manual Calc (3 years)'!Q$1,'BM Data'!$K$1:$BE$1,0)) -> 0.80348 | S3: =INDEX('BM Data'!$K$7:$BE$260,MATCH('Manual Calc (3 years)'!$F7,'BM Data'!$A$7:$A$260,0),MATCH('Manual Calc (3 years)'!S$1,'BM Data'!$K$1:$BE$1,0)) -> 2.22882 | U3: =INDEX('BM Data'!$K$7:$BE$260,MATCH('Manual Calc (3 years)'!$F7,'BM Data'!$A$7:$A$260,0),MATCH('Manual Calc (3 years)'!U$1,'BM Data'!$K$1:$BE$1,0)) -> 0.82534 | W3: =INDEX('BM Data'!$K$7:$BE$260,MATCH('Manual Calc (3 years)'!$F7,'BM Data'!$A$7:$A$260,0),MATCH('Manual Calc (3 years)'!W$1,'BM Data'!$K$1:$BE$1,0)) -> 0.94076 | Y3: =INDEX('BM Data'!$K$7:$BE$260,MATCH('Manual Calc (3 years)'!$F7,'BM Data'!$A$7:$A$260,0),MATCH('Manual Calc (3 years)'!Y$1,'BM Data'!$K$1:$BE$1,0)) -> -0.94336 | AA3: =INDEX('BM Data'!$K$7:$BE$260,MATCH('Manual Calc (3 years)'!$F7,'BM Data'!$A$7:$A$260,0),MATCH('Manual Calc (3 years)'!AA$1,'BM Data'!$K$1:$BE$1,0)) -> 1.77574 | AC3: =INDEX('BM Data'!$K$7:$BE$260,MATCH('Manual Calc (3 years)'!$F7,'BM Data'!$A$7:$A$260,0),MATCH('Manual Calc (3 years)'!AC$1,'BM Data'!$K$1:$BE$1,0)) -> -0.45227 | AE3: =INDEX('BM Data'!$K$7:$BE$260,MATCH('Manual Calc (3 years)'!$F7,'BM Data'!$A$7:$A$260,0),MATCH('Manual Calc (3 years)'!AE$1,'BM Data'!$K$1:$BE$1,0)) -> 1.28107 | AG3: =INDEX('BM Data'!$K$7:$BE$260,MATCH('Manual Calc (3 years)'!$F7,'BM Data'!$A$7:$A$260,0),MATCH('Manual Calc (3 years)'!AG$1,'BM Data'!$K$1:$BE$1,0)) -> 0.10692 | AI3: =INDEX('BM Data'!$K$7:$BE$260,MATCH('Manual Calc (3 years)'!$F7,'BM Data'!$A$7:$A$260,0),MATCH('Manual Calc (3 years)'!AI$1,'BM Data'!$K$1:$BE$1,0)) -> -1.00802 | AK3: =INDEX('BM Data'!$K$7:$BE$260,MATCH('Manual Calc (3 years)'!$F7,'BM Data'!$A$7:$A$260,0),MATCH('Manual Calc (3 years)'!AK$1,'BM Data'!$K$1:$BE$1,0)) -> 1.18781 | AM3: =INDEX('BM Data'!$K$7:$BE$260,MATCH('Manual Calc (3 years)'!$F7,'BM Data'!$A$7:$A$260,0),MATCH('Manual Calc (3 years)'!AM$1,'BM Data'!$K$1:$BE$1,0)) -> 1.2941 | AO3: =INDEX('BM Data'!$K$7:$BE$260,MATCH('Manual Calc (3 years)'!$F7,'BM Data'!$A$7:$A$260,0),MATCH('Manual Calc (3 years)'!AO$1,'BM Data'!$K$1:$BE$1,0)) -> 1.07077 | AQ3: =INDEX('BM Data'!$K$7:$BE$260,MATCH('Manual Calc (3 years)'!$F7,'BM Data'!$A$7:$A$260,0),MATCH('Manual Calc (3 years)'!AQ$1,'BM Data'!$K$1:$BE$1,0)) -> 0.71495 | AS3: =INDEX('BM Data'!$K$7:$BE$260,MATCH('Manual Calc (3 years)'!$F7,'BM Data'!$A$7:$A$260,0),MATCH('Manual Calc (3 years)'!AS$1,'BM Data'!$K$1:$BE$1,0)) -> 1.06078 | AU3: =INDEX('BM Data'!$K$7:$BE$260,MATCH('Manual Calc (3 years)'!$F7,'BM Data'!$A$7:$A$260,0),MATCH('Manual Calc (3 years)'!AU$1,'BM Data'!$K$1:$BE$1,0)) -> 0.46655 | AW3: =INDEX('BM Data'!$K$7:$BE$260,MATCH('Manual Calc (3 years)'!$F7,'BM Data'!$A$7:$A$260,0),MATCH('Manual Calc (3 years)'!AW$1,'BM Data'!$K$1:$BE$1,0)) -> 0.85046 | AY3: =INDEX('BM Data'!$K$7:$BE$260,MATCH('Manual Calc (3 years)'!$F7,'BM Data'!$A$7:$A$260,0),MATCH('Manual Calc (3 years)'!AY$1,'BM Data'!$K$1:$BE$1,0)) -> -0.52841 | BA3: =INDEX('BM Data'!$K$7:$BE$260,MATCH('Manual Calc (3 years)'!$F7,'BM Data'!$A$7:$A$260,0),MATCH('Manual Calc (3 years)'!BA$1,'BM Data'!$K$1:$BE$1,0)) -> -0.0883
A4: Month 34 | B4: ='Invert return series (3 years)'!$B4 -> -0.030244762 | F4: Monthly Excess> | G4: =G2-G3 -> 0.91303386 | I4: =I2-I3 -> 0.24288259 | K4: =K2-K3 -> -0.86304219 | M4: =M2-M3 -> 4.7483197 | O4: =O2-O3 -> 2.4338507 | Q4: =Q2-Q3 -> -2.035417 | S4: =S2-S3 -> -4.002607 | U4: =U2-U3 -> -0.72573132 | W4: =W2-W3 -> -0.083965811 | Y4: =Y2-Y3 -> 1.4431334 | AA4: =AA2-AA3 -> -2.1745631 | AC4: =AC2-AC3 -> 1.328774 | AE4: =AE2-AE3 -> 0.27468984 | AG4: =AG2-AG3 -> -0.90921702 | AI4: =AI2-AI3 -> 3.8286109 | AK4: =AK2-AK3 -> -3.1564165 | AM4: =AM2-AM3 -> 1.0218597 | AO4: =AO2-AO3 -> 0.97646737 | AQ4: =AQ2-AQ3 -> -3.9198931 | AS4: =AS2-AS3 -> -2.6778145 | AU4: =AU2-AU3 -> 2.7471223 | AW4: =AW2-AW3 -> -3.8749362 | AY4: =AY2-AY3 -> -0.3890555 | BA4: =BA2-BA3 -> -1.8278857
A5: Month 33 | B5: ='Invert return series (3 years)'!$B5 -> 0.032136723 | F5: Tracking error | G5: =STDEV(G4,I4,K4,M4,O4,Q4,S4,U4,W4,Y4,AA4,AC4,AE4,AG4,AI4,AK4,AM4,AO4,AQ4,AS4,AU4,AW4,AY4,BA4)*SQRT(12) -> 8.3499603
A6: Month 32 | B6: ='Invert return series (3 years)'!$B6 -> -0.016170345
A7: Month 31 | B7: ='Invert return series (3 years)'!$B7 -> -0.032049431 | D7: Benchmark: | F7: Morningstar AUS Mod Tgt Alloc NR AUD
A8: Month 30 | B8: ='Invert return series (3 years)'!$B8 -> 0.020472374 | D8: 3 yr annualised return: | E8: =VLOOKUP($F$7,'BM Data'!$A:$G,4,FALSE) -> 7.201367
A9: Month 29 | B9: ='Invert return series (3 years)'!$B9 -> 0.023159597 | D9: 2 yr annualised vol: | E9: =VLOOKUP($F$7,'BM Data'!$A:$G,7,FALSE) -> 3.381862
A10: Month 28 | B10: ='Invert return series (3 years)'!$B10 -> -0.019686065
A11: Month 27 | B11: ='Invert return series (3 years)'!$B11 -> 0.028205909
A12: Month 26 | B12: ='Invert return series (3 years)'!$B12 -> -0.0080229702
A13: Month 25 | B13: ='Invert return series (3 years)'!$B13 -> 0.015557598 | D13: Morningstar Category: | F13: Australia Fund Alternative - Other
A14: Month 24 | B14: ='Invert return series (3 years)'!$B14 -> 0.0087650403 | D14: 3 yr 4th Quartile Cut-off Return: | E14: =VLOOKUP($F$13,'Morningstar Category Data'!$A:$E,4,FALSE) -> 3.437971
A15: Month 23 | B15: ='Invert return series (3 years)'!$B15 -> -0.0039882307 | D15: 2 yr Median tracking error: | E15: =VLOOKUP($F$13,'Morningstar Category Data'!$I:$J,2,FALSE) -> 11.011605
A16: Month 22 | B16: ='Invert return series (3 years)'!$B16 -> 0.0049977342
A17: Month 21 | B17: ='Invert return series (3 years)'!$B17 -> 0.0085679419
A18: Month 20 | B18: ='Invert return series (3 years)'!$B18 -> 0.00099608678
A19: Month 19 | B19: ='Invert return series (3 years)'!$B19 -> -0.01773787
A20: Month 18 | B20: ='Invert return series (3 years)'!$B20 -> -0.01231937
A21: Month 17 | B21: ='Invert return series (3 years)'!$B21 -> 0.032476107
A22: Month 16 | B22: ='Invert return series (3 years)'!$B22 -> 0.027364197
A23: Month 15 | B23: ='Invert return series (3 years)'!$B23 -> 0.0072424781
A24: Month 14 | B24: ='Invert return series (3 years)'!$B24 -> 0.0091940259
A25: Month 13 | B25: ='Invert return series (3 years)'!$B25 -> 0.015097839
A26: Month 12 | B26: ='Invert return series (3 years)'!$B26 -> -0.016858346
A27: Month 11 | B27: ='Invert return series (3 years)'!$B27 -> 0.010123351
... A37: Month 1 | B37: ='Invert return series (3 years)'!$B37 -> -0.011368317
A40: Scoring Summary
A41: Fund vs BM. 3 year net returns. Fail if alpha<0 | B41: Fund vs peers. 3 year rank in Morningstar peer group. Fail if in 4th quartile | C41: Annualised 2 year tracking error. Fail if >2x peer median TE | D41: Annualised 2 year volatility. Fail if >1.5x BM volatility | E41: Fail if <80% liquid in 21 business days | F41: Fail if not Approved/Investment Grade (Zenith, Lonsec), 3.5 (SQM) or Neutral (Morningstar) or higher | G41: Team (resourcing, skills, stability) | H41: Process (robust, disciplined, governance) | I41: Business (conflicts, support, stability) | J41: Product (viability, fees, capacity, concentration) | K41: Score | L41: Final Rating
A42: =IF(E2>E8,20,"-") -> - | B42: =IF(E2>E14,20,"-") -> 20 | C42: =IF(G5>(2*E15),"-",5) -> 5 | D42: =IF(E3>(1.5*E9),"-",5) -> - | E42: 10 | G42: 10 | H42: 10 | I42: 5 | J42: 5 | K42: =SUM(A42:J42) -> 65 | L42: =IF(K42<50,"Red",IF(K42>60,"Green","Amber")) -> Green

Sheet Manual Calc (2 years)
B1: Return Series | D1: Investment Option | F1: Investment option monthly returns> | G1: Month 1 | I1: Month 2 | K1: Month 3 | M1: Month 4 | O1: Month 5 | Q1: Month 6 | S1: Month 7 | U1: Month 8 | W1: Month 9 | Y1: Month 10 | AA1: Month 11 | AC1: Month 12 | AE1: Month 13 | AG1: Month 14 | AI1: Month 15 | AK1: Month 16 | AM1: Month 17 | AO1: Month 18 | AQ1: Month 19 | AS1: Month 20 | AU1: Month 21 | AW1: Month 22 | AY1: Month 23 | BA1: Month 24
A2: Month 24 | B2: ='Invert return series (2 years)'!$B2 -> 0.001265213 | D2: 2 yr annualised return: | E2: {=(PRODUCT(1+$B$2:$B$25)^(0.5)-1)*100} -> 10.422398 | G2: =$B25*100 -> 3.070665 | I2: =$B24*100 -> -5.7978741 | K2: =$B23*100 -> 4.9354245 | M2: =$B22*100 -> 0.5765681 | O2: =$B21*100 -> -2.6776591 | Q2: =$B20*100 -> 1.8036866 | S2: =$B19*100 -> 2.051514 | U2: =$B18*100 -> 1.7416475 | W2: =$B17*100 -> 3.4338148 | Y2: =$B16*100 -> 0.093871301 | AA2: =$B15*100 -> -1.603754 | AC2: =$B14*100 -> -10.878218 | AE2: =$B13*100 -> 2.04754 | AG2: =$B12*100 -> -0.63277413 | AI2: =$B11*100 -> 3.5364225 | AK2: =$B10*100 -> 4.6012452 | AM2: =$B9*100 -> -0.88147818 | AO2: =$B8*100 -> 1.5407347 | AQ2: =$B7*100 -> 4.1752524 | AS2: =$B6*100 -> 4.1179419 | AU2: =$B5*100 -> 2.5042679 | AW2: =$B4*100 -> 3.6626656 | AY2: =$B3*100 -> -0.11540287 | BA2: =$B2*100 -> 0.1265213
A3: Month 23 | B3: ='Invert return series (2 years)'!$B3 -> -0.0011540287 | D3: 2 yr annualised vol: | E3: =(STDEV($B$2:$B$25)*SQRT(12))*100 -> 12.395555 | F3: Benchmark monthly returns> | G3: =INDEX('BM Data'!$K$7:$BE$260,MATCH('Manual Calc (2 years)'!$F7,'BM Data'!$A$7:$A$260,0),MATCH('Manual Calc (2 years)'!G$1,'BM Data'!$K$1:$BE$1,0)) -> 0.01506 | I3: =INDEX('BM Data'!$K$7:$BE$260,MATCH('Manual Calc (2 years)'!$F7,'BM Data'!$A$7:$A$260,0),MATCH('Manual Calc (2 years)'!I$1,'BM Data'!$K$1:$BE$1,0)) -> 0.79921 | K3: =INDEX('BM Data'!$K$7:$BE$260,MATCH('Manual Calc (2 years)'!$F7,'BM Data'!$A$7:$A$260,0),MATCH('Manual Calc (2 years)'!K$1,'BM Data'!$K$1:$BE$1,0)) -> 1.4799 | M3: =INDEX('BM Data'!$K$7:$BE$260,MATCH('Manual Calc (2 years)'!$F7,'BM Data'!$A$7:$A$260,0),MATCH('Manual Calc (2 years)'!M$1,'BM Data'!$K$1:$BE$1,0)) -> -0.7255 | O3: =INDEX('BM Data'!$K$7:$BE$260,MATCH('Manual Calc (2 years)'!$F7,'BM Data'!$A$7:$A$260,0),MATCH('Manual Calc (2 years)'!O$1,'BM Data'!$K$1:$BE$1,0)) -> 1.11126 | Q3: =INDEX('BM Data'!$K$7:$BE$260,MATCH('Manual Calc (2 years)'!$F7,'BM Data'!$A$7:$A$260,0),MATCH('Manual Calc (2 years)'!Q$1,'BM Data'!$K$1:$BE$1,0)) -> 0.56979 | S3: =INDEX('BM Data'!$K$7:$BE$260,MATCH('Manual Calc (2 years)'!$F7,'BM Data'!$A$7:$A$260,0),MATCH('Manual Calc (2 years)'!S$1,'BM Data'!$K$1:$BE$1,0)) -> 1.73315 | U3: =INDEX('BM Data'!$K$7:$BE$260,MATCH('Manual Calc (2 years)'!$F7,'BM Data'!$A$7:$A$260,0),MATCH('Manual Calc (2 years)'!U$1,'BM Data'!$K$1:$BE$1,0)) -> 1.64181 | W3: =INDEX('BM Data'!$K$7:$BE$260,MATCH('Manual Calc (2 years)'!$F7,'BM Data'!$A$7:$A$260,0),MATCH('Manual Calc (2 years)'!W$1,'BM Data'!$K$1:$BE$1,0)) -> 1.69939 | Y3: =INDEX('BM Data'!$K$7:$BE$260,MATCH('Manual Calc (2 years)'!$F7,'BM Data'!$A$7:$A$260,0),MATCH('Manual Calc (2 years)'!Y$1,'BM Data'!$K$1:$BE$1,0)) -> -0.15724 | AA3: =INDEX('BM Data'!$K$7:$BE$260,MATCH('Manual Calc (2 years)'!$F7,'BM Data'!$A$7:$A$260,0),MATCH('Manual Calc (2 years)'!AA$1,'BM Data'!$K$1:$BE$1,0)) -> 1.28995 | AC3: =INDEX('BM Data'!$K$7:$BE$260,MATCH('Manual Calc (2 years)'!$F7,'BM Data'!$A$7:$A$260,0),MATCH('Manual Calc (2 years)'!AC$1,'BM Data'!$K$1:$BE$1,0)) -> -0.25624 | AE3: =INDEX('BM Data'!$K$7:$BE$260,MATCH('Manual Calc (2 years)'!$F7,'BM Data'!$A$7:$A$260,0),MATCH('Manual Calc (2 years)'!AE$1,'BM Data'!$K$1:$BE$1,0)) -> 1.33452 | AG3: =INDEX('BM Data'!$K$7:$BE$260,MATCH('Manual Calc (2 years)'!$F7,'BM Data'!$A$7:$A$260,0),MATCH('Manual Calc (2 years)'!AG$1,'BM Data'!$K$1:$BE$1,0)) -> 0.76972 | AI3: =INDEX('BM Data'!$K$7:$BE$260,MATCH('Manual Calc (2 years)'!$F7,'BM Data'!$A$7:$A$260,0),MATCH('Manual Calc (2 years)'!AI$1,'BM Data'!$K$1:$BE$1,0)) -> -0.96199 | AK3: =INDEX('BM Data'!$K$7:$BE$260,MATCH('Manual Calc (2 years)'!$F7,'BM Data'!$A$7:$A$260,0),MATCH('Manual Calc (2 years)'!AK$1,'BM Data'!$K$1:$BE$1,0)) -> -0.03016 | AM3: =INDEX('BM Data'!$K$7:$BE$260,MATCH('Manual Calc (2 years)'!$F7,'BM Data'!$A$7:$A$260,0),MATCH('Manual Calc (2 years)'!AM$1,'BM Data'!$K$1:$BE$1,0)) -> 1.64521 | AO3: =INDEX('BM Data'!$K$7:$BE$260,MATCH('Manual Calc (2 years)'!$F7,'BM Data'!$A$7:$A$260,0),MATCH('Manual Calc (2 years)'!AO$1,'BM Data'!$K$1:$BE$1,0)) -> 1.68905 | AQ3: =INDEX('BM Data'!$K$7:$BE$260,MATCH('Manual Calc (2 years)'!$F7,'BM Data'!$A$7:$A$260,0),MATCH('Manual Calc (2 years)'!AQ$1,'BM Data'!$K$1:$BE$1,0)) -> 0.84725 | AS3: =INDEX('BM Data'!$K$7:$BE$260,MATCH('Manual Calc (2 years)'!$F7,'BM Data'!$A$7:$A$260,0),MATCH('Manual Calc (2 years)'!AS$1,'BM Data'!$K$1:$BE$1,0)) -> 1.0837 | AU3: =INDEX('BM Data'!$K$7:$BE$260,MATCH('Manual Calc (2 years)'!$F7,'BM Data'!$A$7:$A$260,0),MATCH('Manual Calc (2 years)'!AU$1,'BM Data'!$K$1:$BE$1,0)) -> 0.58797 | AW3: =INDEX('BM Data'!$K$7:$BE$260,MATCH('Manual Calc (2 years)'!$F7,'BM Data'!$A$7:$A$260,0),MATCH('Manual Calc (2 years)'!AW$1,'BM Data'!$K$1:$BE$1,0)) -> 1.03466 | AY3: =INDEX('BM Data'!$K$7:$BE$260,MATCH('Manual Calc (2 years)'!$F7,'BM Data'!$A$7:$A$260,0),MATCH('Manual Calc (2 years)'!AY$1,'BM Data'!$K$1:$BE$1,0)) -> 0.44207 | BA3: =INDEX('BM Data'!$K$7:$BE$260,MATCH('Manual Calc (2 years)'!$F7,'BM Data'!$A$7:$A$260,0),MATCH('Manual Calc (2 years)'!BA$1,'BM Data'!$K$1:$BE$1,0)) -> 0.74981
A4: Month 22 | B4: ='Invert return series (2 years)'!$B4 -> 0.036626656 | F4: Monthly Excess> | G4: =G2-G3 -> 3.055605 | I4: =I2-I3 -> -6.5970841 | K4: =K2-K3 -> 3.4555245 | M4: =M2-M3 -> 1.3020681 | O4: =O2-O3 -> -3.7889191 | Q4: =Q2-Q3 -> 1.2338966 | S4: =S2-S3 -> 0.31836402 | U4: =U2-U3 -> 0.09983752 | W4: =W2-W3 -> 1.7344248 | Y4: =Y2-Y3 -> 0.2511113 | AA4: =AA2-AA3 -> -2.893704 | AC4: =AC2-AC3 -> -10.621978 | AE4: =AE2-AE3 -> 0.71302001 | AG4: =AG2-AG3 -> -1.4024941 | AI4: =AI2-AI3 -> 4.4984125 | AK4: =AK2-AK3 -> 4.6314052 | AM4: =AM2-AM3 -> -2.5266882 | AO4: =AO2-AO3 -> -0.14831533 | AQ4: =AQ2-AQ3 -> 3.3280024 | AS4: =AS2-AS3 -> 3.0342419 | AU4: =AU2-AU3 -> 1.9162979 | AW4: =AW2-AW3 -> 2.6280056 | AY4: =AY2-AY3 -> -0.55747287 | BA4: =BA2-BA3 -> -0.6232887
A5: Month 21 | B5: ='Invert return series (2 years)'!$B5 -> 0.025042679 | F5: Tracking error | G5: =STDEV(G4,I4,K4,M4,O4,Q4,S4,U4,W4,Y4,AA4,AC4,AE4,AG4,AI4,AK4,AM4,AO4,AQ4,AS4,AU4,AW4,AY4,BA4)*SQRT(12) -> 12.268674
A6: Month 20 | B6: ='Invert return series (2 years)'!$B6 -> 0.041179419
A7: Month 19 | B7: ='Invert return series (2 years)'!$B7 -> 0.041752524 | D7: Benchmark: | F7: Bloomberg Global High Yield TR Hdg AUD
A8: Month 18 | B8: ='Invert return series (2 years)'!$B8 -> 0.015407347 | D8: 2 yr annualised return: | E8: =VLOOKUP($F$7,'BM Data'!$A:$G,6,FALSE) -> 9.555733
A9: Month 17 | B9: ='Invert return series (2 years)'!$B9 -> -0.0088147818 | D9: 2 yr annualised vol: | E9: =VLOOKUP($F$7,'BM Data'!$A:$G,7,FALSE) -> 2.711053
A10: Month 16 | B10: ='Invert return series (2 years)'!$B10 -> 0.046012452
A11: Month 15 | B11: ='Invert return series (2 years)'!$B11 -> 0.035364225
A12: Month 14 | B12: ='Invert return series (2 years)'!$B12 -> -0.0063277413
A13: Month 13 | B13: ='Invert return series (2 years)'!$B13 -> 0.0204754 | D13: Morningstar Category: | F13: Australia Fund Alternative - Macro Trading
A14: Month 12 | B14: ='Invert return series (2 years)'!$B14 -> -0.10878218 | D14: 2 yr 4th Quartile Cut-off Return: | E14: =VLOOKUP($F$13,'Morningstar Category Data'!$A:$E,3,FALSE) -> -1.255531
A15: Month 11 | B15: ='Invert return series (2 years)'!$B15 -> -0.01603754 | D15: 2 yr Median tracking error: | E15: =VLOOKUP($F$13,'Morningstar Category Data'!$I:$J,2,FALSE) -> 11.186195
A16: Month 10 | B16: ='Invert return series (2 years)'!$B16 -> 0.00093871301
A17: Month 9 | B17: ='Invert return series (2 years)'!$B17 -> 0.034338148
A18: Month 8 | B18: ='Invert return series (2 years)'!$B18 -> 0.017416475
A19: Month 7 | B19: ='Invert return series (2 years)'!$B19 -> 0.02051514
A20: Month 6 | B20: ='Invert return series (2 years)'!$B20 -> 0.018036866
A21: Month 5 | B21: ='Invert return series (2 years)'!$B21 -> -0.026776591
A22: Month 4 | B22: ='Invert return series (2 years)'!$B22 -> 0.005765681
A23: Month 3 | B23: ='Invert return series (2 years)'!$B23 -> 0.049354245
A24: Month 2 | B24: ='Invert return series (2 years)'!$B24 -> -0.057978741
A25: Month 1 | B25: ='Invert return series (2 years)'!$B25 -> 0.03070665
A28: Scoring Summary
A29: Fund vs BM. 2 year net returns. Fail if alpha<0 | B29: Fund vs peers. 2 year rank in Morningstar peer group. Fail if in 4th quartile | C29: Annualised 2 year tracking error. Fail if >2x peer median TE | D29: Annualised 2 year volatility. Fail if >1.5x BM volatility | E29: Fail if <80% liquid in 21 business days | F29: Fail if not Approved/Investment Grade (Zenith, Lonsec), 3.5 (SQM) or Neutral (Morningstar) or higher | G29: Team (resourcing, skills, stability) | H29: Process (robust, disciplined, governance) | I29: Business (conflicts, support, stability) | J29: Product (viability, fees, capacity, concentration) | K29: Score | L29: Final Rating
A30: =IF(E2>E8,20,"-") -> 20 | B30: =IF(E2>E14,20,"-") -> 20 | C30: =IF(G5>(2*E15),"-",5) -> 5 | D30: =IF(E3>(1.5*E9),"-",5) -> - | E30: 10 | G30: 10 | H30: 10 | I30: 5 | J30: 5 | K30: =SUM(A30:J30) -> 85 | L30: =IF(K30<50,"Red",IF(K30>60,"Green","Amber")) -> Green

Sheet Morningstar Category Data
A1: 4th Quartile Category Returns | I1: Median Category TE
A2: Morningstar Categories (31 Dec 2025) | B2: 1 Year | C2: 2 Years | D2: 3 Years | E2: 5 Years | I2: Morningstar Categories (31 Dec 2025) | J2: 2 Years
A3: Australia Fund Alternative - Macro Trading | B3: -4.826621 | C3: -1.255531 | D3: 1.364369 | E3: 1.054108 | I3: Australia Fund Alternative - Macro Trading | J3: 11.186195 | L3: 11.186195
A4: Australia Fund Alternative - Multistrategy | B4: 4.871406 | C4: 5.651317 | D4: 6.294975 | E4: 5.129028 | I4: Australia Fund Alternative - Multistrategy | J4: 10.509394 | L4: 10.509394
A5: Australia Fund Alternative - Other | B5: 2.028752 | C5: 4.263378 | D5: 3.437971 | E5: 1.836301 | I5: Australia Fund Alternative - Other | J5: 11.011605 | L5: 11.011605
A6: Australia Fund Alternative - Systematic Trend | B6: 2.065401 | C6: 3.141138 | D6: 1.892295 | E6: 4.067185 | I6: Australia Fund Alternative - Systematic Trend | J6: 13.333063 | L6: 13.333063
A7: Australia Fund Australian Cash | B7: 3.976694 | C7: 4.197108 | D7: 4.081719 | E7: 2.703786 | I7: Australia Fund Australian Cash | J7: 0.067356 | L7: 0.067356
A8: Australia Fund Australian Short Term Fixed Interest | B8: 4.227854 | C8: 4.49918 | D8: 4.357877 | E8: 2.862583 | I8: Australia Fund Australian Short Term Fixed Interest | J8: 0.276417 | L8: 0.276417
A9: Australia Fund Bonds - Australia | B9: 2.917516 | C9: 2.774295 | D9: 3.500913 | E9: -0.748842 | I9: Australia Fund Bonds - Australia | J9: 0.390321 | L9: 0.390321
A10: Australia Fund Bonds - Emerging Market Debt | B10: 12.250659 | C10: 8.558974 | D10: 8.702037 | E10: -0.338676 | I10: Australia Fund Bonds - Emerging Market Debt | J10: 6.235418 | L10: 6.235418
A11: Australia Fund Bonds - Global | B11: 4.09684 | C11: 2.5749 | D11: 3.333599 | E11: -1.333749 | I11: Australia Fund Bonds - Global | J11: 0.943908 | L11: 0.943908
A12: Australia Fund Bonds - Global / Australia | B12: 4.051782 | C12: 2.999734 | D12: 3.743944 | E12: -0.634365 | I12: Australia Fund Bonds - Global / Australia | J12: 0.98566 | L12: 0.98566
A13: Australia Fund Bonds - Inflation-linked | B13: 1.78533 | C13: 0.447276 | D13: 3.165272 | E13: -0.231252 | I13: Australia Fund Bonds - Inflation-linked | J13: 2.129815 | L13: 2.129815
A14: Australia Fund Commodities & Precious Metals | B14: 51.784353 | C14: 42.32934 | D14: 31.299259 | E14: 16.218238 | I14: Australia Fund Commodities & Precious Metals | J14: 23.877368 | L14: 23.877368
A15: Australia Fund Diversified Credit | B15: 5.021038 | C15: 5.106361 | D15: 5.407998 | E15: 2.297666 | I15: Australia Fund Diversified Credit | J15: 3.665483 | L15: 3.665483
A16: Australia Fund Australia Equity Income | B16: 5.375341 | C16: 5.989496 | D16: 6.834276 | E16: 7.560119 | I16: Australia Fund Australia Equity Income | J16: 4.444865 | K16: New Peer Group | L16: 4.444865
A17: Australia Fund Equity Asia Pacific w/o Japan | B17: 13.001158 | C17: 18.607074 | D17: 11.10338 | E17: 5.000682 | I17: Australia Fund Equity Asia Pacific w/o Japan | J17: 6.35787 | L17: 6.35787
A18: Australia Fund Equity Australia Large Blend | B18: 6.235883 | C18: 8.189298 | D18: 8.562284 | E18: 8.025206 | I18: Australia Fund Equity Australia Large Blend | J18: 2.849924 | L18: 2.849924
A19: Australia Fund Equity Australia Large Geared | B19: 1.254876 | C19: 9.477726 | D19: 11.361641 | E19: 10.441292 | I19: Australia Fund Equity Australia Large Geared | J19: 12.366682 | L19: 12.366682
A20: Australia Fund Equity Australia Large Growth | B20: -9.671288 | C20: 2.30309 | D20: 8.088135 | E20: 3.803866 | I20: Australia Fund Equity Australia Large Growth | J20: 6.374814 | L20: 6.374814
A21: Australia Fund Equity Australia Large Value | B21: 4.263558 | C21: 6.489516 | D21: 6.254033 | E21: 8.167696 | I21: Australia Fund Equity Australia Large Value | J21: 3.727303 | L21: 3.727303
A22: Australia Fund Equity Australia Long Short | B22: 7.433136 | C22: 5.901951 | D22: 6.230103 | E22: 6.295768 | I22: Australia Fund Equity Australia Long Short | J22: 8.585015 | L22: 8.585015
A23: Australia Fund Equity Australia Mid/Small Blend | B23: 12.025828 | C23: 11.224768 | D23: 10.167329 | E23: 5.362855 | I23: Australia Fund Equity Australia Mid/Small Blend | J23: 7.957892 | L23: 7.957892
A24: Australia Fund Equity Australia Mid/Small Growth | B24: -1.01519 | C24: 8.868575 | D24: 10.024472 | E24: 2.916581 | I24: Australia Fund Equity Australia Mid/Small Growth | J24: 8.755063 | L24: 8.755063
A25: Australia Fund Equity Australia Mid/Small Value | B25: 8.266127 | C25: 10.841429 | D25: 11.320505 | E25: 9.014166 | I25: Australia Fund Equity Australia Mid/Small Value | J25: 9.44535 | L25: 9.44535
A26: Australia Fund Equity Australia Other | B26: 7.193372 | C26: 8.131666 | D26: 8.523926 | E26: 7.075629 | I26: Australia Fund Equity Australia Other | J26: 11.648779 | L26: 11.648779
A27: Australia Fund Equity Australia Real Estate | B27: 8.936854 | C27: 12.386949 | D27: 13.409132 | E27: 7.938494 | I27: Australia Fund Equity Australia Real Estate | J27: 1.35508 | L27: 1.35508
A28: Australia Fund Equity Emerging Markets | B28: 18.703339 | C28: 14.41817 | D28: 14.07947 | E28: 4.361566 | I28: Australia Fund Equity Emerging Markets | J28: 4.858408 | L28: 4.858408
... A62: Australia Fund Unconstrained Fixed Income | B62: 4.165955 | C62: 5.046363 | D62: 5.471164 | E62: 2.14285 | I62: Australia Fund Unconstrained Fixed Income | J62: 3.188445 | L62: 3.188445
A63: Australia Fund Reserve Backed | I63: Australia Fund Reserve Backed
A64: Australia Fund Unlisted and Direct Property | B64: 1.647436 | C64: -4.90543 | D64: -5.824458 | E64: -1.290515 | I64: Australia Fund Unlisted and Direct Property | J64: 16.691281 | L64: 16.691281
A65: Australia Fund Alternative - Private Debt | B65: 7.704317 | C65: 8.235877 | D65: 8.513764 | E65: 7.151331 | I65: Australia Fund Alternative - Private Debt | J65: 2.752517 | L65: 2.752517
A66: Australia Fund Non Investment Grade Debt | B66: 4.939721 | C66: 6.406669 | D66: 7.094707 | E66: 3.252213 | I66: Australia Fund Non Investment Grade Debt | J66: 2.05497 | L66: 2.05497
A67: Australia Fund Alternative - Private Equity | B67: -8.539211 | C67: -3.128872 | D67: -5.621465 | E67: 2.45875 | I67: Australia Fund Alternative - Private Equity | J67: 8.029192 | L67: 8.029192
A68: Australia Fund Equity Alternative - Private Debt | B68: 4.939721 | C68: 6.406669 | D68: 7.094707 | E68: 3.252213 | I68: Australia Fund Equity Alternative - Private Debt | J68: 2.752517 | L68: 2.752517
A69: Australia Invst Bd Equity Australia Large Blend | B69: 4.718023 | C69: 5.456103 | D69: 6.441186 | E69: 5.82846 | I69: Australia Invst Bd Equity Australia Large Blend | J69: 5.554619 | L69: 5.554619

Sheet BM Data
B1: 5 year Return | D1: 3 year Return | F1: 2 year Return | G1: 2 year Vol | I1: 1 year Return | K1: Month 1 | M1: Month 2 | O1: Month 3 | Q1: Month 4 | S1: Month 5 | U1: Month 6 | W1: Month 7 | Y1: Month 8 | AA1: Month 9 | AC1: Month 10 | AE1: Month 11 | AG1: Month 12 | AI1: Month 13 | AK1: Month 14 | AM1: Month 15 | AO1: Month 16 | AQ1: Month 17 | AS1: Month 18 | AU1: Month 19 | AW1: Month 20 | AY1: Month 21 | BA1: Month 22 | BC1: Month 23 | BE1: Month 24
A4: Group/Investment | B4: Return (Annualized) | D4: Return (Annualized) | F4: Return (Annualized) | G4: Std Dev (Annualized) | I4: Return (Cumulative) | K4: Return (Cumulative) | M4: Return (Cumulative) | O4: Return (Cumulative) | Q4: Return (Cumulative) | S4: Return (Cumulative) | U4: Return (Cumulative) | W4: Return (Cumulative) | Y4: Return (Cumulative) | AA4: Return (Cumulative) | AC4: Return (Cumulative) | AE4: Return (Cumulative) | AG4: Return (Cumulative) | AI4: Return (Cumulative) | AK4: Return (Cumulative) | AM4: Return (Cumulative) | AO4: Return (Cumulative) | AQ4: Return (Cumulative) | AS4: Return (Cumulative) | AU4: Return (Cumulative) | AW4: Return (Cumulative) | AY4: Return (Cumulative) | BA4: Return (Cumulative) | BC4: Return (Cumulative) | BE4: Return (Cumulative)
A6: Unclassified
A7: 35FTSE EPRANAREIT Dev H + 45FTSE Dev Core Infra 5050 H + 20S&PASX 200 AREIT | B7: 6.966644 | D7: 9.6068 | F7: 10.814072 | G7: 9.61355 | I7: 10.742233 | K7: -1.914453 | M7: 1.278615 | O7: 4.962044 | Q7: -4.219876 | S7: 3.713545 | U7: -0.682853 | W7: 6.161281 | Y7: 3.29047 | AA7: 3.196299 | AC7: -2.13471 | AE7: 3.237188 | AG7: -5.717517 | AI7: 2.112899 | AK7: 0.518019 | AM7: -1.284542 | AO7: 1.195402 | AQ7: 2.566931 | AS7: 0.64192 | AU7: 1.295565 | AW7: 2.812308 | AY7: 0.501973 | BA7: -0.251214 | BC7: 1.331767 | BE7: -1.100711
A8: 50 BB AusBond Bank 0+ 50 BB AusBond Composite | B8: 1.16169 | D8: 3.940045 | F8: 3.646627 | G8: 1.592446 | I8: 3.5767 | K8: 0.288004 | M8: 0.022105 | O8: 0.74441 | Q8: -0.816054 | S8: 0.383935 | U8: 0.561548 | W8: 0.926253 | Y8: 0.792808 | AA8: 0.333304 | AC8: -0.753587 | AE8: 0.748033 | AG8: 0.441824 | AI8: 0.28491 | AK8: 0.633189 | AM8: 0.260554 | AO8: 1.026124 | AQ8: 0.253154 | AS8: 0.533194 | AU8: 0.132832 | AW8: 0.327579 | AY8: 0.196004 | BA8: 0.328736 | BC8: -0.29155 | BE8: -0.158893
A9: 50 Bloomberg AusBond Composite 0+Y TR and 50 BBg Barclay Aggregate TR Hdg | B9: -0.498486 | D9: 3.853058 | F9: 3.189625 | G9: 2.998521 | I9: 3.796815 | K9: -0.053206 | M9: -0.552553 | O9: 0.965773 | Q9: -1.843563 | S9: 0.583692 | U9: 0.778861 | W9: 1.680482 | Y9: 1.096544 | AA9: 0.689468 | AC9: -1.694264 | AE9: 1.148437 | AG9: -0.174943 | AI9: 0.28548 | AK9: 1.062176 | AM9: -0.132002 | AO9: 1.322385 | AQ9: -0.098152 | AS9: 0.826962 | AU9: -0.093712 | AW9: 0.414508 | AY9: 0.389428 | BA9: 0.554046 | BC9: -0.351382 | BE9: -0.430282
A10: 50 JPM EMBI (hedged) + 50 JPM EMBI
A11: 50 MSCI %0 AUD CASH | B11: 9.157971 | D11: 12.91167 | F11: 12.703663 | G11: 4.795691 | I11: 8.307305 | K11: 2.447925 | M11: 3.13743 | O11: 1.697593 | Q11: -1.449072 | S11: 1.195702 | U11: 0.985697 | W11: 2.22677 | Y11: -0.434777 | AA11: -0.053418 | AC11: 2.147561 | AE11: 2.771587 | AG11: 1.476201 | AI11: 1.55691 | AK11: -0.01163 | AM11: -2.158774 | AO11: -0.749031 | AQ11: 2.8431 | AS11: 1.387173 | AU11: 1.724963 | AW11: 0.619657 | AY11: 1.145515 | BA11: 1.813449 | BC11: 0.233538 | BE11: -0.296879
A12: 50 MSCI EM NR AUD 50 MSCI WORLD SMALL CAP | B12: 9.047306 | D12: 16.341698 | F12: 18.459175 | G12: 8.318843 | I12: 17.657622 | K12: -0.602944 | M12: 5.628516 | O12: 2.988586 | Q12: -1.899362 | S12: 0.137126 | U12: 0.57629 | W12: 5.929591 | Y12: -2.744275 | AA12: 1.982295 | AC12: 2.136657 | AE12: 1.987407 | AG12: 2.005957 | AI12: 1.869402 | AK12: -1.113002 | AM12: -1.772412 | AO12: -1.629881 | AQ12: 4.431803 | AS12: 3.474521 | AU12: 3.389284 | AW12: 1.539759 | AY12: 3.265198 | BA12: 3.438757 | BC12: -0.516413 | BE12: 0.270661
A13: 50% ASX 300 TR + 50% MSCI World ex Aus unhedged | B13: 12.810354 | D13: 16.75878 | F13: 16.285759 | G13: 7.94662 | I13: 11.709678 | K13: 2.81047 | M13: 3.453791 | O13: 3.141474 | Q13: -3.092421 | S13: 1.433481 | U13: 1.262201 | W13: 4.105314 | Y13: -0.400038 | AA13: 1.301654 | AC13: 1.312166 | AE13: 4.431346 | AG13: -0.24891 | AI13: 3.601047 | AK13: -2.073141 | AM13: -4.005146 | AO13: 0.878825 | AQ13: 4.768455 | AS13: 1.936442 | AU13: 2.775533 | AW13: 2.042428 | AY13: 0.669685 | BA13: 1.868903 | BC13: -1.235299 | BE13: 0.231502
A14: 50% ASX Midcap 50% Small Ord | B14: 8.606015 | D14: 13.159128 | F14: 15.925845 | G14: 10.61524 | I14: 21.663912 | K14: -0.637157 | M14: 3.532378 | O14: 4.114997 | Q14: -2.593691 | S14: 0.235112 | U14: -1.390603 | W14: 3.827937 | Y14: -0.023771 | AA14: 4.062023 | AC14: -0.808597 | AE14: 3.51137 | AG14: -3.418339 | AI14: 5.074138 | AK14: -3.721536 | AM14: -3.562271 | AO14: 2.596834 | AQ14: 5.851573 | AS14: 0.812176 | AU14: 3.565044 | AW14: 6.969734 | AY14: 1.910656 | BA14: 1.393785 | BC14: -0.587237 | BE14: 0.091768
A15: 50% AusBond Bank, 50% AusBond Composite | B15: 1.16169 | D15: 3.940045 | F15: 3.646627 | G15: 1.592446 | I15: 3.5767 | K15: 0.288004 | M15: 0.022105 | O15: 0.74441 | Q15: -0.816054 | S15: 0.383935 | U15: 0.561548 | W15: 0.926253 | Y15: 0.792808 | AA15: 0.333304 | AC15: -0.753587 | AE15: 0.748033 | AG15: 0.441824 | AI15: 0.28491 | AK15: 0.633189 | AM15: 0.260554 | AO15: 1.026124 | AQ15: 0.253154 | AS15: 0.533194 | AU15: 0.132832 | AW15: 0.327579 | AY15: 0.196004 | BA15: 0.328736 | BC15: -0.29155 | BE15: -0.158893
A16: 50% AusBond Comp 0-3yr, 50% AusBond Bank | B16: 2.281767 | D16: 3.947622 | F16: 4.038378 | G16: 0.49201 | I16: 3.793179 | K16: 0.369488 | M16: 0.248483 | O16: 0.408033 | Q16: 0.062184 | S16: 0.379225 | U16: 0.320222 | W16: 0.591341 | Y16: 0.495377 | AA16: 0.36848 | AC16: 0.085815 | AE16: 0.414194 | AG16: 0.460743 | AI16: 0.397923 | AK16: 0.373544 | AM16: 0.379788 | AO16: 0.598634 | AQ16: 0.339978 | AS16: 0.36071 | AU16: 0.217824 | AW16: 0.328058 | AY16: 0.188674 | BA16: 0.275633 | BC16: 0.121385 | BE16: 0.147584
A17: 50% Ausbond Comp, 50% Global Agg hdg | B17: -0.498486 | D17: 3.853058 | F17: 3.189625 | G17: 2.998521 | I17: 3.796815 | K17: -0.053206 | M17: -0.552553 | O17: 0.965773 | Q17: -1.843563 | S17: 0.583692 | U17: 0.778861 | W17: 1.680482 | Y17: 1.096544 | AA17: 0.689468 | AC17: -1.694264 | AE17: 1.148437 | AG17: -0.174943 | AI17: 0.28548 | AK17: 1.062176 | AM17: -0.132002 | AO17: 1.322385 | AQ17: -0.098152 | AS17: 0.826962 | AU17: -0.093712 | AW17: 0.414508 | AY17: 0.389428 | BA17: 0.554046 | BC17: -0.351382 | BE17: -0.430282
A18: 50% FTSE EPRANAREIT Developed (H) + 50% FTSE Dvlp Core Infra 5050 (H) | B18: 5.611656 | D18: 7.496292 | F18: 8.975552 | G18: 9.50603 | I18: 10.113163 | K18: -2.807677 | M18: 0.232806 | O18: 3.736174 | Q18: -3.573862 | S18: 3.946863 | U18: -0.816522 | W18: 5.937561 | Y18: 4.044487 | AA18: 2.344168 | AC18: -2.233006 | AE18: 3.292283 | AG18: -5.765688 | AI18: 1.48827 | AK18: 2.155673 | AM18: -0.668099 | AO18: -0.158752 | AQ18: 1.979022 | AS18: 0.315691 | AU18: 0.681036 | AW18: 2.492718 | AY18: 1.322726 | BA18: -0.500563 | BC18: 2.520102 | BE18: -1.846626
A19: 50% MSCI ACWI Info Tech + 50% MSCI ACWI Financials | B19: 17.82624 | D19: 29.605142 | F19: 28.232324 | G19: 10.841328 | I19: 25.485112 | K19: 2.738112 | M19: 5.223656 | O19: 3.510727 | Q19: -3.765873 | S19: 5.623825 | U19: 4.475002 | W19: 1.32439 | Y19: 1.596342 | AA19: 1.382658 | AC19: 0.604794 | AE19: 5.727108 | AG19: -0.663618 | AI19: 2.380216 | AK19: -0.275808 | AM19: -5.688702 | AO19: 0.284828 | AQ19: 7.702486 | AS19: 5.954264 | AU19: 3.064059 | AW19: 1.402069 | AY19: 4.427542 | BA19: 3.428558 | BC19: -1.327759 | BE19: 2.24167
A20: 50% MSCI World Small Cap (unhedged) 50% MSCI EM NR AUD | B20: 9.047306 | D20: 16.341698 | F20: 18.459175 | G20: 8.318843 | I20: 17.657622 | K20: -0.602944 | M20: 5.628516 | O20: 2.988586 | Q20: -1.899362 | S20: 0.137126 | U20: 0.57629 | W20: 5.929591 | Y20: -2.744275 | AA20: 1.982295 | AC20: 2.136657 | AE20: 1.987407 | AG20: 2.005957 | AI20: 1.869402 | AK20: -1.113002 | AM20: -1.772412 | AO20: -1.629881 | AQ20: 4.431803 | AS20: 3.474521 | AU20: 3.389284 | AW20: 1.539759 | AY20: 3.265198 | BA20: 3.438757 | BC20: -0.516413 | BE20: 0.270661
A21: 50% S&PASX 200 + 50% Bbg AusBond Comp | B21: 4.758851 | D21: 7.581365 | F21: 6.98616 | G21: 5.481076 | I21: 6.813422 | K21: 0.696715 | M21: 0.245687 | O21: 2.198084 | Q21: -2.459875 | S21: 0.654959 | U21: 0.89319 | W21: 2.835664 | Y21: 0.837807 | AA21: 1.6376 | AC21: -1.593788 | AE21: 2.461979 | AG21: -1.322423 | AI21: 2.380685 | AK21: -1.430682 | AM21: -1.609023 | AO21: 2.660174 | AQ21: 2.18331 | AS21: 1.081531 | AU21: 1.161365 | AW21: 1.719115 | AY21: -0.340868 | BA21: 0.374439 | BC21: -1.769823 | BE21: 0.335492
A22: 50% S&PASX 300 A-REIT TR + 50% FTSE EPRANAREIT Developed Index TR (hedge | B22: 8.102878 | D22: 11.695876 | F22: 10.742876 | G22: 11.072803 | I22: 6.497197 | K22: 0.159222 | M22: 2.862207 | O22: 6.494448 | Q22: -6.558911 | S22: 1.469451 | U22: 0.16355 | W22: 7.628084 | Y22: 1.445324 | AA22: 3.668053 | AC22: -0.983137 | AE22: 2.669977 | AG22: -3.953499 | AI22: 2.794295 | AK22: -1.769806 | AM22: -3.57451 | AO22: 2.327862 | AQ22: 3.471154 | AS22: 0.456361 | AU22: 2.010019 | AW22: 3.553891 | AY22: -1.568892 | BA22: 0.154574 | BC22: -0.90978 | BE22: -0.345143
