Workbook
Name DS: #REF!
Name FAC_WealthPlus: #REF!+#REF!
Name Input_PDS: #REF!
Name Template: #REF!

Sheet Summary
A1: Managed Portfolio Fee Calculation Tool | E1: 4 | F1: 5 | G1: 6 | H1: 7 | I1: 8 | J1: 9 | K1: 10
K3: Inputs | O3: Admin Fee | Q3: Fees % p.a. | U3: Fees by balance tier $
K4: Menu | L4: Partner | M4: Partner | O4: Balance | P4: Min | Q4: Select | R4: Partner | S4: Choice (Super / Pension) | T4: Choice (IDPS) | U4: Select | V4: Partner
K5: Account Balance $ | L5: 250000 | M5: 250000 | O5: $0 - $350,000 | P5: 0 | Q5: 0.002 | R5: 0.0023 | S5: 0.0028 | T5: 0.0025 | U5: 0 | V5: 0
K6: Managed Portfolio Balance % | L6: 0.96 | M6: 0.96 | O6: $350,001 - $750,000 | P6: 350000 | Q6: 0.0012 | R6: 0.0014 | S6: 0.0017 | T6: 0.0015 | U6: =Q5*($P6-$P5) -> 700 | V6: =R5*($P6-$P5) -> 805
K7: Platform Cash Balance % | L7: 0.04 | M7: 0.04 | O7: $750,001 - $1,000,000 | P7: 750000 | Q7: 0.001 | R7: 0.0011 | S7: 0.0012 | T7: 0.001 | U7: =U6+Q6*($P7-$P6) -> 1180 | V7: =V6+R6*($P7-$P6) -> 1365
K8: Account Fee $ p.a. | L8: 180 | M8: 180 | O8: $1,000,001 - $1,250,000 | P8: 1000000 | Q8: 0.0008 | R8: 0.0008 | S8: 0.0008 | T8: 0.0008 | U8: =U7+Q7*($P8-$P7) -> 1430 | V8: =V7+R7*($P8-$P7) -> 1640
K9: Cash Account Investment Fee % p.a. | L9: 0.0075 | M9: 0.0075 | O9: $1,250,000 + | P9: 1250000 | Q9: 0 | R9: 0 | S9: 0 | T9: 0 | U9: =U8+Q8*($P9-$P8) -> 1630 | V9: =V8+R8*($P9-$P8) -> 1840
K10: Trade Fee % | L10: 0.001 | M10: 0.001
K11: Turnover % p.a. | L11: 0.3 | M11: 0.3
K12: Trustee Fee % p.a. | L12: 0.00015 | M12: 0.00015
K13: Performance Fee % p.a. | L13: 0 | M13: 0
K14: Rebate %p.a. | L14: =SUMIF(Component!$A$2:$A$452,L17,Component!$G$2:$G$452) -> 0 | M14: =SUMIF(Component!$A$2:$A$452,M17,Component!$G$2:$G$452) -> 0.021 | O14: `
I16: Portfolio fees and costs
L17: NTH0619 | M17: NTH0620
K18: Fee Type | L18: =VLOOKUP(L17,IMFee!$A:$B,2,FALSE) -> Aurora Defensive Managed Portfolio | M18: =VLOOKUP(M17,IMFee!$A:$B,2,FALSE) -> Aurora Growth Managed Portfolio
K19: Investment management fee % p.a. | L19: =VLOOKUP(L17,IMFee!$A:$K,11,FALSE) -> 0.0016 | M19: =VLOOKUP(M17,IMFee!$A:$K,11,FALSE) -> 0.0017
K20: Estimated underlying management fees and costs % p.a. | L20: =ROUND(SUMPRODUCT(L$58:L$81,$F$58:$F$81)-L14,4) -> 0 | M20: =ROUND(SUMPRODUCT(M$58:M$81,$F$58:$F$81)-M14,4) -> -0.0137
K21: Estimated managed portfolio cash investment fee % p.a. | L21: =ROUND(SUMPRODUCT(L$58:L$951,$G$58:$G$951),6) -> 0 | M21: =ROUND(SUMPRODUCT(M$58:M$951,$G$58:$G$951),6) -> 0.00015
K22: Performance fees % p.a. | L22: =L$13 -> 0 | M22: =M$13 -> 0
K23: Estimated underlying performance fees % p.a. | L23: =ROUND(SUMPRODUCT(L$58:L$951,$H$58:$H$951),4) -> 0 | M23: =ROUND(SUMPRODUCT(M$58:M$951,$H$58:$H$951),4) -> 0.002
K24: Estimated gross transaction costs % p.a. | L24: =ROUND(SUMPRODUCT(L$58:L$951,$I$58:$I$951),4) -> 0 | M24: =ROUND(SUMPRODUCT(M$58:M$951,$I$58:$I$951),4) -> 0.0009
K25: Estimated Buy spread & | L25: =ROUND(SUMPRODUCT(L$58:L$951,$J$58:$J$951),4) -> 0 | M25: =ROUND(SUMPRODUCT(M$58:M$951,$J$58:$J$951),4) -> 0.0016
K26: Estimated Sell spread % | L26: =ROUND(SUMPRODUCT(L$58:L$951,$K$58:$K$951),4) -> 0 | M26: =ROUND(SUMPRODUCT(M$58:M$951,$K$58:$K$951),4) -> 0.0016
K27: Total | L27: =L19+L20+L21+L22+L23+L24 -> 0.0016 | M27: =M19+M20+M21+M22+M23+M24 -> -0.00895
H29: Total fees and costs
L30: =L17 -> NTH0619 | M30: =M17 -> NTH0620
K31: Fee Type | L31: =L18 -> Aurora Defensive Managed Portfolio | M31: =M18 -> Aurora Growth Managed Portfolio
K32: Total portfolio fees and costs % p.a. | L32: =SUM(L36:L42)/L$5 -> 0.001536 | M32: =SUM(M36:M42)/M$5 -> -0.008592
K33: Total platform administration fees % p.a. | L33: =SUM(L44:L48)/L$5 -> 0.003458 | M33: =SUM(M44:M48)/M$5 -> 0.003458
K34: Grand total estimated fees and costs % p.a. | L34: =L32+L33 -> 0.004994 | M34: =M32+M33 -> -0.005134
K36: Portfolio investment management fees | L36: =L$5*L$6*L19 -> 384 | M36: =M$5*M$6*M19 -> 408
K37: Portfolio estimated underlying management fees and costs | L37: =L$5*L$6*L20 -> 0 | M37: =M$5*M$6*M20 -> -3288
K38: Portfolio estimated cash investment fees | L38: =L$5*L$6*L21 -> 0 | M38: =M$5*M$6*M21 -> 36
K39: Portfolio performance fees | L39: =L$5*L$6*L22 -> 0 | M39: =M$5*M$6*M22 -> 0
K40: Portfolio estimated underlying performance fees | L40: =L$5*L$6*L23 -> 0 | M40: =M$5*M$6*M23 -> 480
K41: Portfolio estimated gross transaction costs | L41: =L$5*L$6*ROUND(SUMPRODUCT(L$58:L$951,$I$58:$I$951),4) -> 0 | M41: =M$5*M$6*ROUND(SUMPRODUCT(M$58:M$951,$I$58:$I$951),4) -> 216
K42: Portfolio estimated trade fees | L42: =L$5*L$6*L$10*L$11*L53 -> 0 | M42: =M$5*M$6*M$10*M$11*M53 -> 0
K43: Total estimated portfolio fees and costs $ p.a. | L43: =SUM(L36:L42) -> 384 | M43: =SUM(M36:M42) -> -2148
K44: Account fee | L44: =L$8 -> 180 | M44: =M$8 -> 180
...

Sheet IMFee
A1: Investment Management Fees (p.a.)
A2: ModelID | B2: ModelDescription | C2: IM Fee % (excl. GST) | D2: IM Fee % (GST) | E2: IM Fee % (RITC) | F2: IM Fee % (incl. GST) (less RITC) | G2: RE Fee % (excl. GST) | H2: RE Fee % (GST) | I2: RE Fee % (RITC) | J2: RE Fee % (incl. GST) (less RITC) | K2: Client Fee % (Rounded) (IM Fee + RE Fee + GST - RITC)
A3: NTH0619 | B3: Aurora Defensive Managed Portfolio | C3: 0.00075 | D3: =C3*0.1 -> 7.5e-05 | E3: =D3*0.75 -> 5.625e-05 | F3: =C3+D3-E3 -> 0.00076875 | G3: 0.0008 | H3: =G3*0.1 -> 8e-05 | I3: =H3*0.55 -> 4.4e-05 | J3: =G3+H3-I3 -> 0.000836 | K3: =ROUND(F3+J3,4) -> 0.0016
A4: NTH0620 | B4: Aurora Growth Managed Portfolio | C4: 0.0008 | D4: =C4*0.1 -> 8e-05 | E4: =D4*0.75 -> 6e-05 | F4: =C4+D4-E4 -> 0.00082 | G4: 0.0008 | H4: =G4*0.1 -> 8e-05 | I4: =H4*0.55 -> 4.4e-05 | J4: =G4+H4-I4 -> 0.000836 | K4: =ROUND(F4+J4,4) -> 0.0017

Sheet Data Source>

Sheet ComponentFee
D1: Underlying Asset Fees and Costs
A2: Asset Type | B2: Asset Class | C2: TradeType | D2: UnitID | E2: UnitName | F2: Status | G2: Estimated underlying management fees and costs % p.a. | H2: Estimated managed portfolio cash investment fee % p.a. | I2: Estimated underlying performance fees % p.a. | J2: Estimated gross transaction costs % p.a. | K2: Estimated underlying buy spread % | L2: Estimated underlying sell spread % | M2: PDS Link | N2: PDS date
C3: NONEXCHG | D3: AAP0103 | E3: Ausbil Australian Active Equity Fund | F3: OPEN | G3: 0.009 | H3: 0 | I3: 0 | J3: 0.0006 | K3: 0.002 | L3: 0.002 | M3: https://www.ausbil.com.au/CMSPages/GetFile.aspx?guid=71ec5a50-77c5-4ebd-8828-691219bfab8a
C4: NONEXCHG | D4: BFL0020 | E4: Quay Global Real Estate-Daily Series | F4: OPEN | G4: 0.0088 | H4: 0 | I4: 0.0037 | J4: 0.0011 | K4: 0.002 | L4: 0.002 | M4: https://www.quaygi.com/quay-global-real-estate-fund | N4: 45631
C5: NONEXCHG | D5: BTA0313 | E5: Pendal MidCap Fund | F5: OPEN | G5: 0.009 | H5: 0 | I5: 0 | J5: 0.002 | K5: 0.0025 | L5: 0.0025 | M5: https://www.pendalgroup.com/pendal-midcap-fund | N5: 45761
C6: NONEXCHG | D6: BTA8657 | E6: Pendal Dynamic Income Fund | F6: OPEN | G6: 0.0055 | H6: 0 | I6: 0 | J6: 0.0016 | K6: 0.0012 | L6: 0.0012 | M6: https://pendalgroup.com/wp-content/uploads/docs/factsheets/PDS/Pendal%20Dynamic%20Income%20Fund%20-%20PDS%20-%20Class%20R.pdf?v=2025-04-221745299193 | N6: 45555
C7: NONEXCHG | D7: CASHACCT | E7: Cash Account | F7: OPEN | G7: 0 | H7: 0.0075 | I7: 0 | J7: 0 | K7: 0 | L7: 0 | N7: 45537
C8: NONEXCHG | D8: CSA0038 | E8: Bentham Global Income Fund (W) | F8: OPEN | G8: 0.0077 | H8: 0 | I8: 0 | J8: 0.0001 | K8: 0.002 | L8: 0.002 | M8: https://fidante.com/au/Offer-Documents | N8: 45643
C9: NONEXCHG | D9: ETL0016 | E9: PIMCO Diversified Fixed Interest Fund — Wholesale Class | F9: OPEN | G9: 0.0056 | H9: 0 | I9: 0 | J9: 0.0004 | K9: 0 | L9: 0.001 | M9: https://fund-ui.pimco.com/fund-detail-api/api/funds/documents/content/view?documentId=hy1jSu7qu_tgkxzWKGHUF1BXmUSpzIpDrzm2B6eHkmw | N9: 45789
C10: NONEXCHG | D10: ETL0060 | E10: Allan Gray Australia Equity Fund - Class A | F10: OPEN | G10: 0.0021 | H10: 0 | I10: 0 | J10: 0.0002 | K10: 0.002 | L10: 0.002 | M10: https://www.allangray.com.au/documents/Allan-Gray-Australia-Equity-Fund-Class-A-PDS-and-Application-form-Australian-and-NZ-investors.pdf | N10: 45617
C11: NONEXCHG | D11: ETL0463 | E11: Orbis Global Equity Fund | F11: OPEN | G11: 0.0107 | H11: 0 | I11: 0 | J11: 0.0009 | K11: 0.0025 | L11: 0.0025 | M11: https://www.orbis.com/au/investor/funds/orbis-global-equity-fund#downloads | N11: 45164
C12: NONEXCHG | D12: FID0010 | E12: Fidelity Asia Fund | F12: OPEN | G12: 0.0115 | H12: 0 | I12: 0 | J12: 0.0019 | K12: 0.003 | L12: 0.003 | M12: https://www.fidelity.com.au/funds/fidelity-asia-fund/related-documents/product-disclosure-statement/ | N12: 45449
C13: NONEXCHG | D13: FRT0027 | E13: Franklin Australian Absolute Return Bond Fund | F13: OPEN | G13: 0.005 | H13: 0 | I13: 0 | J13: 0.0008 | K13: 0 | L13: 0 | M13: https://www.franklintempleton.com.au/our-products/funds-prices-performance/managed-funds/products/19414/W/franklin-australian-absolute-return-bond-fund/FRT0027AU#documents | N13: 45565
C14: NONEXCHG | D14: GSF0874 | E14: Munro Global Growth Small&Mid Cap Fund - Class A | F14: OPEN | G14: 0.011 | H14: 0 | I14: 0.0183 | J14: 0 | K14: 0 | L14: 0.0015 | M14: https://northonline.amp.com.au/NorthOnline/ViewDoc.aspx?documenttype=1&Type=APIR&Code=GSF0874AU | N14: 45573
C15: NONEXCHG | D15: MAQ0464 | E15: Arrowstreet Global Equity Fund | F15: OPEN | G15: 0.0128 | H15: 0 | I15: 0 | J15: 0.00062 | K15: 0.0016 | L15: 0.0017 | M15: https://mim.fgsfulfillment.com/download.aspx?sku=PDS-AGEF-ANZ | N15: 45611
C16: NONEXCHG | D16: MAQ3897 | E16: Macquarie Dynamic Bond No. 1 Fund - Class W | F16: OPEN | G16: 0.0049 | H16: 0 | I16: 4e-05 | J16: 0.00141 | K16: 0.001 | L16: 0.0017 | M16: https://mim.fgsfulfillment.com/download.aspx?sku=PDS-MDBF-ANZ | N16: 45901
C17: NONEXCHG | D17: MGE0005 | E17: Magellan Global Opportunities Fund No. 2 - Class A | F17: OPEN | G17: 0.0075 | H17: 0 | I17: 0 | J17: 0.0003 | K17: 0.001 | L17: 0.001 | M17: https://northonline.amp.com.au/NorthOnline/ViewDoc.aspx?documenttype=1&Type=APIR&Code=MGE0005AU | N17: 45838
C18: NONEXCHG | D18: SCH0028 | E18: Schroder Fixed Income Fund (W) | F18: OPEN | G18: 0.0045 | H18: 0 | I18: 0 | J18: 0.0006 | K18: 0.0012 | L18: 0.0012 | N18: 45789
C19: NONEXCHG | D19: TGP0034 | E19: ClearBridge RARE Infrastructure Value Fund – Unhedged | F19: OPEN | G19: 0.0097 | H19: 0 | I19: 0 | J19: 0.0007 | K19: 0.001 | L19: 0.001 | M19: https://www.clearbridgeinvestments.com.au/forms-downloads/clearbridge-product-disclosure-statements/clearbridge-rare-infrastructure-value-fund-unhedged-class-a-units-product-disclosure-statement/ | N19: 46008
C20: NONEXCHG | D20: UBS0003 | E20: UBS Income Solution Fund | F20: OPEN | G20: 0.006 | H20: 0 | I20: 0 | J20: 0 | K20: 0.001 | L20: 0.002 | N20: 45849
C21: NONEXCHG | D21: VAN0002 | E21: Vanguard Australian Shares Index Fund (W) | F21: OPEN | G21: 0.0016 | H21: 0 | I21: 0 | J21: 0 | K21: 0.0004 | L21: 0.0004 | M21: https://fund-docs.vanguard.com/AU-PDS-Vanguard_Australian_Shares_Index_Fund.pdf | N21: 45901
C22: NONEXCHG | D22: VAN0003 | E22: Vanguard International Shares Index Fund | F22: OPEN | G22: 0.0018 | H22: 0 | I22: 0 | J22: 0.0001 | K22: 0.0005 | L22: 0.0005 | M22: https://fund-docs.vanguard.com/AU-PDS-Vanguard_International_Shares_Index_Fund.pdf | N22: 45764
C23: NONEXCHG | D23: VAN0004 | E23: Vanguard Australian Property Securities Index Fund (W) | F23: OPEN | G23: 0.0023 | H23: 0 | I23: 0 | J23: 0.0001 | K23: 0.0005 | L23: 0.0005 | M23: https://fund-docs.vanguard.com/AU-PDS-Vanguard_Australian_Property_Securities_Index_Fund.pdf | N23: 45901
C24: NONEXCHG | D24: WHT1465 | E24: Plato Global Alpha Fund | F24: OPEN | G24: 0.0088 | H24: 0 | I24: 0.0118 | J24: 0.0041 | K24: 0.003 | L24: 0.003 | M24: https://plato.com.au/wp-content/uploads/Plato-Global-Alpha-Fund-PDS.pdf | N24: 45901
C25: NONEXCHG | D25: WHT3093 | E25: Firetrail Australian Small Companies Fund | F25: OPEN | G25: 0.0085 | H25: 0 | I25: 0.0141 | J25: 0.0027 | K25: 0.003 | L25: 0.003 | M25: 0 | N25: 45596
C26: NONEXCHG | D26: WPC1583 | E26: Daintree High Income Trust | F26: OPEN | G26: 0.0075 | H26: 0 | I26: 0 | J26: 0.0015 | K26: 0.0015 | L26: 0.0015 | M26: https://daintreecapital.com.au/wp-content/uploads/2022/07/Daintree-High-Income-Trust-PDS.pdf | N26: 45751

Sheet Rebate
A1: Unit ID | B1: APIR | C1: Fund name | D1: Rebate
A2: =LEFT(B2,7) -> AAP0103 | B2: AAP0103AU | C2: Ausbil Australian Active Fund - Wholesale class | D2: 0.002
A3: =LEFT(B3,7) -> BFL0020 | B3: BFL0020AU | C3: Quay Global Real Estate Fund (Unhedged) | D3: 0.0012
A4: =LEFT(B4,7) -> BTA0313 | B4: BTA0313AU | C4: Pendal MidCap | D4: 0.0015
A5: =LEFT(B5,7) -> BTA8657 | B5: BTA8657AU | C5: Pendal Dynamic Income Fund | D5: 0.0015
A6: =LEFT(B6,7) -> CSA0038 | B6: CSA0038AU | C6: Bentham Professional Global Income P | D6: 0.0025
A7: =LEFT(B7,7) -> ETL0016 | B7: ETL0016AU | C7: PIMCO Diversified Fixed Interest - Institutional Class | D7: 0.0005
A8: =LEFT(B8,7) -> ETL0060 | B8: ETL0060AU | C8: Allan Gray Australia Equity Fund B | D8: 0
A9: =LEFT(B9,7) -> ETL0463 | B9: ETL0463AU | C9: Orbis Global Equity Fund (Australia Registered) - Retail Class | D9: 0.002
A10: =LEFT(B10,7) -> FID0010 | B10: FID0010AU | C10: Fidelity Asia | D10: 0.002
A11: =LEFT(B11,7) -> FRT0027 | B11: FRT0027AU | C11: Franklin Templeton Absolute Return Bond | D11: 0.001
A12: =LEFT(B12,7) -> GSF0874 | B12: GSF0874AU | C12: Munro Global Growth Small & Mid Cap Fund | D12: 0
A13: =LEFT(B13,7) -> MAQ0464 | B13: MAQ0464AU | C13: Arrowstreet Global Equity No 2 (Class I) | D13: 0.0053
... A24: =LEFT(B24,7) -> WPC1583 | B24: WPC1583AU | C24: Daintree High Income Trust | D24: 0.0015

Sheet Component
A1: Investment Components
A2: ModelID | B2: ModelDescription | C2: UnitID | D2: Percentage | E2: TradeType | F2: Percentage * 100 | G2: Rebate
A3: NTH0620 | B3: Lumina Growth Managed Portfolio | C3: AAP0103 | D3: 0.11 | E3: =INDEX(ComponentFee!C:C,MATCH(C3,ComponentFee!D:D,0)) -> NONEXCHG | F3: =D3*100 -> 11 | G3: =VLOOKUP(C3,Rebate!A:D,4) -> 0.002
A4: NTH0620 | B4: Lumina Growth Managed Portfolio | C4: VAN0002 | D4: 0.1 | E4: =INDEX(ComponentFee!C:C,MATCH(C4,ComponentFee!D:D,0)) -> NONEXCHG | F4: =D4*100 -> 10 | G4: =VLOOKUP(C4,Rebate!A:D,4) -> 0
A5: NTH0620 | B5: Lumina Growth Managed Portfolio | C5: VAN0003 | D5: 0.1 | E5: =INDEX(ComponentFee!C:C,MATCH(C5,ComponentFee!D:D,0)) -> NONEXCHG | F5: =D5*100 -> 10 | G5: =VLOOKUP(C5,Rebate!A:D,4) -> 0
A6: NTH0620 | B6: Lumina Growth Managed Portfolio | C6: TGP0034 | D6: 0.09 | E6: =INDEX(ComponentFee!C:C,MATCH(C6,ComponentFee!D:D,0)) -> NONEXCHG | F6: =D6*100 -> 9 | G6: =VLOOKUP(C6,Rebate!A:D,4) -> 0.0015
A7: NTH0620 | B7: Lumina Growth Managed Portfolio | C7: MAQ0464 | D7: 0.08 | E7: =INDEX(ComponentFee!C:C,MATCH(C7,ComponentFee!D:D,0)) -> NONEXCHG | F7: =D7*100 -> 8 | G7: =VLOOKUP(C7,Rebate!A:D,4) -> 0.0053
A8: NTH0620 | B8: Lumina Growth Managed Portfolio | C8: ETL0060 | D8: 0.07 | E8: =INDEX(ComponentFee!C:C,MATCH(C8,ComponentFee!D:D,0)) -> NONEXCHG | F8: =D8*100 -> 7 | G8: =VLOOKUP(C8,Rebate!A:D,4) -> 0
A9: NTH0620 | B9: Lumina Growth Managed Portfolio | C9: FID0010 | D9: 0.07 | E9: =INDEX(ComponentFee!C:C,MATCH(C9,ComponentFee!D:D,0)) -> NONEXCHG | F9: =D9*100 -> 7 | G9: =VLOOKUP(C9,Rebate!A:D,4) -> 0.002
A10: NTH0620 | B10: Lumina Growth Managed Portfolio | C10: WHT1465 | D10: 0.06 | E10: =INDEX(ComponentFee!C:C,MATCH(C10,ComponentFee!D:D,0)) -> NONEXCHG | F10: =D10*100 -> 6 | G10: =VLOOKUP(C10,Rebate!A:D,4) -> 0.001
A11: NTH0620 | B11: Lumina Growth Managed Portfolio | C11: ETL0463 | D11: 0.06 | E11: =INDEX(ComponentFee!C:C,MATCH(C11,ComponentFee!D:D,0)) -> NONEXCHG | F11: =D11*100 -> 6 | G11: =VLOOKUP(C11,Rebate!A:D,4) -> 0.002
A12: NTH0620 | B12: Lumina Growth Managed Portfolio | C12: MGE0005 | D12: 0.05 | E12: =INDEX(ComponentFee!C:C,MATCH(C12,ComponentFee!D:D,0)) -> NONEXCHG | F12: =D12*100 -> 5 | G12: =VLOOKUP(C12,Rebate!A:D,4) -> 0.001
A13: NTH0620 | B13: Lumina Growth Managed Portfolio | C13: BFL0020 | D13: 0.05 | E13: =INDEX(ComponentFee!C:C,MATCH(C13,ComponentFee!D:D,0)) -> NONEXCHG | F13: =D13*100 -> 5 | G13: =VLOOKUP(C13,Rebate!A:D,4) -> 0.0012
A14: NTH0620 | B14: Lumina Growth Managed Portfolio | C14: BTA0313 | D14: 0.04 | E14: =INDEX(ComponentFee!C:C,MATCH(C14,ComponentFee!D:D,0)) -> NONEXCHG | F14: =D14*100 -> 4 | G14: =VLOOKUP(C14,Rebate!A:D,4) -> 0.0015
... A27: NTH0621 | B27: Lumina Defensive Managed Portfolio | C27: CASHACCT | D27: 0.02 | E27: =INDEX(ComponentFee!C:C,MATCH(C27,ComponentFee!D:D,0)) -> NONEXCHG | F27: =D27*100 -> 2 | G27: =VLOOKUP(C27,Rebate!A:D,4) -> 0.0015
