Workbook

Sheet Page One - IM Info
B2: MyNorth Investment Manager Onboarding Questionnaire
B3: Page One: Investment Manager Information
B4: All information required
G6: =D6 -> 0
B7: Part 1 - About the Investment Manager | D7: Response | E7: Progress | F7: =COUNTA(D8:F21)/ROWS(D8:F21) -> 1 | G7: =D7 -> Response
B8: 1 | C8: Investment Manager's full legal entity name as per ABN | D8: Salita Portfolio Services Pty Ltd | G8: =D8 -> Salita Portfolio Services Pty Ltd
B9: 2 | C9: Australian Business Number (ABN) | D9: 39 609 946 616 | G9: =D9 -> 39 609 946 616
B10: 3 | C10: Australian Financial Services License (AFSL) | D10: Salita Portfolio Services Pty Ltd is a corporate authorised representative of Personal Financial Services Ltd (PFS) CAR 1241713 | G10: =D10 -> Salita Portfolio Services Pty Ltd is a corporate authorised representative of Personal Financial Services Ltd (PFS) CAR 1241713
B11: =B10+1 -> 4 | C11: Street Address | D11: Level 6 88 Phillip Street Sydney NSW 2000 | G11: =D11 -> Level 6 88 Phillip Street Sydney NSW 2000
B12: =B11+1 -> 5 | C12: Postal Address | D12: Level 6 88 Phillip Street Sydney NSW 2001 | G12: =D12 -> Level 6 88 Phillip Street Sydney NSW 2001
B13: =B12+1 -> 6 | C13: Telephone number | D13: 0407494569 | G13: =D13 -> 0407494569
B14: =B13+1 -> 7 | C14: Email (General) | D14: jcarnevale@entireti.com.au | G14: =D14 -> jcarnevale@entireti.com.au
B15: =B14+1 -> 8 | C15: Email (Invoices) | D15: jcarnevale@entireti.com.au | G15: =D15 -> jcarnevale@entireti.com.au
B16: =B15+1 -> 9 | C16: Overview of the Investment Manager's business - Include any corporate authorised representative or if any other relevant entities different to the AFSL holder involved in the management/construction of the portfolio | D16: Salita Portfolio Services (“Salita”) is a wholly owned subsidiary of Entireti Limited and a corporate authorised representative of Personal Financial Services. Established in 2016, Salita provides professional investment research, analysis, and management services for a suite of managed portfolios. The Salita investment team oversees daily operations, drawing on the resources of the Entireti Group and external consultants to ensure a prudent, informed, and professional approach to implementing Salita’s investment philosophy across diverse portfolios tailored to specific risk and return objectives. | G16: =D16 -> Salita Portfolio Services (“Salita”) is a wholly owned subsidiary of Entireti Limited and a corporate authorised representative of Personal Financial Services. Established in 2016, Salita provides professional investment research, analysis, and management services for a suite of managed portfolios. The Salita investment team oversees daily operations, drawing on the resources of the Entireti Group and external consultants to ensure a prudent, informed, and professional approach to implementing Salita’s investment philosophy across diverse portfolios tailored to specific risk and return objectives.
B17: =B16+1 -> 10 | C17: About the investment manager (this is for disclosure purposes and should not include quantitative information that may go out of date quickly) (250 words max) | D17: Salita Portfolio Services (“Salita”) is a wholly owned subsidiary of Entireti Limited and a corporate authorised representative of Personal Financial Services. Established in 2016, Salita provides professional investment research, analysis, and management services for a suite of managed portfolios. The Salita investment team oversees daily operations, drawing on the resources of the Entireti Group and external consultants to ensure a prudent, informed, and professional approach to implementing Salita’s investment philosophy across diverse portfolios tailored to specific risk and return objectives.
B18: =B17+1 -> 11 | C18: Describe the investment philosophy and process | D18: At Salita Portfolio Services, the approach to portfolio construction is driven by the following investment principles: • Growing and preserving capital - The overarching goal is to grow investor wealth over time whilst minimising the risk of permanent capital loss. Whilst negative returns may be experienced over various time periods, Salita Portfolio Services' focus is on minimising drawdowns and preserving capital over the medium to long term. • Long term approach - Salita Portfolio Services ensures the Strategic Asset Allocation (SAA) is aligned to client risk profiles. The SAA is built around medium to long term capital market assumptions and is reviewed annually to ensure consistency with overall portfolio objectives. Salita Portfolio Services believe that timing the market is difficult and therefore do not intend to take a short-term tactical asset allocation approach. Rather they interrogate the SAA on a regular basis to determine if changes are warranted to support a high conviction medium term view. • Managing turnover - As part of a longer-term approach, Salita Portfolio Services aim to keep turnover within the portfolio to a minimum. Part of this approach is to ensure investment products are measured over the appropriate time horizon. • Active and passive investment strategies - Salita Portfolio Services assess the merits of active management across each asset class and will use active management where they have strong conviction that it will lead to a superior outcome, either via outperformance and/or lowering drawdown risk. Typically, this results in a blend of active and passive investment strategies in portfolios. • A focus on fees - Assessing the level and appropriateness of fees, both at the individual investment product and overall portfolio level is an important feature of Salita Portfolio Services' approach. Lower fees are the preference but paying an appropriate fee to gain access to superior investment skills is also worthy of consideration. • Diversification - Salita Portfolio Services believe that diversification is an effective way to manage risk. It enables portfolios to perform through varied market conditions and not be wholly reliant on a particular style (i.e. Growth or Value) being in favour. | G18: =D18 -> At Salita Portfolio Services, the approach to portfolio construction is driven by the following investment principles: • Growing and preserving capital - The overarching goal is to grow investor wealth over time whilst minimising the risk of permanent capital loss. Whilst negative returns may be experienced over various time periods, Salita Portfolio Services' focus is on minimising drawdowns and preserving capital over the medium to long term. • Long term approach - Salita Portfolio Services ensures the Strategic Asset Allocation (SAA) is aligned to client risk profiles. The SAA is built around medium to long term capital market assumptions and is reviewed annually to ensure consistency with overall portfolio objectives. Salita Portfolio Services believe that timing the market is difficult and therefore do not intend to take a short-term tactical asset allocation approach. Rather they interrogate the SAA on a regular basis to determine if changes are warranted to support a high conviction medium term view. • Managing turnover - As part of a longer-term approach, Salita Portfolio Services aim to keep turnover within the portfolio to a minimum. Part of this approach is to ensure investment products are measured over the appropriate time horizon. • Active and passive investment strategies - Salita Portfolio Services assess the merits of active management across each asset class and will use active management where they have strong conviction that it will lead to a superior outcome, either via outperformance and/or lowering drawdown risk. Typically, this results in a blend of active and passive investment strategies in portfolios. • A focus on fees - Assessing the level and appropriateness of fees, both at the individual investment product and overall portfolio level is an important feature of Salita Portfolio Services' approach. Lower fees are the preference but paying an appropriate fee to gain access to superior investment skills is also worthy of consideration. • Diversification - Salita Portfolio Services believe that diversification is an effective way to manage risk. It enables portfolios to perform through varied market conditions and not be wholly reliant on a particular style (i.e. Growth or Value) being in favour.
B19: =B18+1 -> 12 | C19: Investment philosophy and process (this is for disclosure purposes and should not include quantitative information that may go out of date quickly) (180 words max) | D19: Salita Portfolio Services focuses on growing and preserving capital while minimising permanent loss. We avoid short-term tactical shifts, instead reviewing the Strategic Asset Allocation regularly to support high-conviction medium-term views. We maintain low turnover and blend active and passive strategies, using active management where conviction is strong. Fees are assessed carefully, balancing cost with value. Diversification across styles reduces volatility and enhances consistency, ensuring portfolios perform across varied market conditions while supporting sustainable, long-term wealth creation.
B20: =B19+1 -> 13 | C20: What is the strategy's capacity and FUM? | D20: N/A
B21: =B20+1 -> 14 | C21: What is the company's website? | D21: https://salitaportfolioservices.com.au/ | G21: =D21 -> https://salitaportfolioservices.com.au/
G22: =D22 -> 0
B23: Part 2 - About the Portfolio Manager | D23: Response | E23: Progress | F23: =COUNTA(D24:F26)/ROWS(D24:F26) -> 1 | G23: =D23 -> Response
B24: 1 | C24: Name of portfolio manager | D24: Aman Ramrakha | G24: =D24 -> Aman Ramrakha
B25: 2 | C25: Company position of portfolio manager (include any qualification reference) | D25: Chief Investment Officer | G25: =D25 -> Chief Investment Officer
B26: 3 | C26: Brief bio of portfolio manager | D26: Aman brings over 30 years’ experience in financial services, spanning technical, consulting, and advisory roles. Before joining Entireti in 2025, he was Executive Director of Research at Rainmaker Information. His career includes senior positions at Morningstar, where he oversaw Manager Research and provided investment consulting services, and at Commonwealth Bank, where he led investment and insurance research for over $60B of funds under advice. Aman has also held roles at BT Financial Group, Colonial First State, KPMG and Commonwealth Private. He holds a Bachelor of Commerce, a Graduate Diploma in Applied Finance and Investments, a Diploma of Financial Planning, and is a Certified Investment Management Consultant. | G26: =D26 -> Aman brings over 30 years’ experience in financial services, spanning technical, consulting, and advisory roles. Before joining Entireti in 2025, he was Executive Director of Research at Rainmaker Information. His career includes senior positions at Morningstar, where he oversaw Manager Research and provided investment consulting services, and at Commonwealth Bank, where he led investment and insurance research for over $60B of funds under advice. Aman has also held roles at BT Financial Group, Colonial First State, KPMG and Commonwealth Private. He holds a Bachelor of Commerce, a Graduate Diploma in Applied Finance and Investments, a Diploma of Financial Planning, and is a Certified Investment Management Consultant.
G27: =D27 -> 0
B28: Part 3 - Portfolio attachment checklist | D28: Response | E28: Progress | F28: =COUNTA(D29:F35)/ROWS(D29:F35) -> 1 | G28: =D28 -> Response
B29: 1 | C29: FSC Document or standard RFP | D29: Not available | G29: =D29 -> Not available
B30: 2 | C30: Monthly return series of flagship SMAs since inception | D30: Attached
B31: 4 | C31: Pitch pack / fact sheet (Investment Team, process, portfolio & performance) | D31: Attached | G31: =D31 -> Attached
B32: 5 | C32: Certificates of Insurance | D32: Attached | G32: =D32 -> Attached
B33: 6 | C33: Copy of AFSL | D33: Not available | G33: =D33 -> Not available
B34: 7 | C34: Conflicts of Interest Policy | D34: Attached | G34: =D34 -> Attached
B35: 8 | C35: Any relevant biographies or org charts | D35: Attached | G35: =D35 -> Attached
B37: Part 4 - Corporate Actions likelihood of involvement | D37: Response | E37: Progress | F37: =COUNTA(D38:F44)/ROWS(D38:F44) -> 1
B38: 1 | C38: Interest to participate in IPOs? | D38: No
B39: 2 | C39: Interest to participate in placements? | D39: No
B40: 3 | C40: Interest to participate in entitlements? | D40: No
B41: 4 | C41: Interest to participate in rights issues? | D41: No
B42: 5 | C42: Interest to participate in SPPs? | D42: No
B43: 6 | C43: Interest to participate in bonus option issues? | D43: No
...

Sheet Page Two - IM Info contd
B2: MyNorth Investment Manager Onboarding Questionnaire
B3: Page Two: Investment Manager Information
B4: All information required - Insert new rows as required
B7: Part 6 - Current Investment Team | D7: Response
B8: Name & title/position | D8: Number of years with the firm | E8: Total years of investment experience | F8: Describe their role and contribution to the strategy
C9: John Carnevale (Executive GM – Investment Services) | D9: 6 | E9: 35 | F9: Oversight of Research & Investment Team
C10: Aman Ramrakha (Chief Investment Officer) | D10: <1 | E10: 30 | F10: Overall responsibility for portfolios
C11: Tim Schroeders (Senior Portfolio Manager) | D11: 6 | E11: 30 | F11: Overall responsibility for portfolios
C12: Sean Webster (Head of Research & Senior Portfolio Manager) | D12: 7 | E12: 29 | F12: Provides portfolio management support
C13: Calvin Yap (Senior Investment Research Analyst) | D13: 3 | E13: 4 | F13: Provides support to portfolio managers
C14: Julia Tao (Senior Investment Research Analyst) | D14: 6 | E14: 18 | F14: Provides support to portfolio managers
C15: Frank Mach (Investment Research Analyst) | D15: 5 | E15: 15 | F15: Provides support to portfolio managers
C16: Cindy Zhao (Manager, Investment Governance) | D16: 5 | E16: 15 | F16: Governance oversight for portfolios
C17: Ekta Badola (Investmengt Research Analyst) | D17: 2 | E17: 5 | F17: Provides support to portfolio managers
B19: Team additions in the last three years
B20: Name & title/position | D20: Date joined | E20: Total years of investment experience | F20: Previous employment
C21: Aman Ramrakha (Chief Investment Officer) | D21: 45686 | E21: 30 | F21: Rainmaker, Morningstar, CBA
B24: Team departures in the last three years
B25: Name & title/position | D25: Date joined | E25: Date departed | F25: Reason for departure
C26: Ian Holliday (Head of Research Services) | D26: 43405

Sheet Page Four - Portfolio Details
B2: MyNorth Investment Manager Onboarding Questionnaire
B3: Page Four: Portfolio Details
B4: All information required
B6: Part 1: General portfolio details | D6: Response | G6: Progress | H6: =COUNTA(D7:H19)/ROWS(D7:H19) -> 1 | L6: Part 1: General portfolio details | N6: Response | Q6: Progress | R6: =COUNTA(N7:R19)/ROWS(N7:R19) -> 1 | V6: Part 1: General portfolio details | X6: Response | AA6: Progress | AB6: =COUNTA(X7:AB19)/ROWS(X7:AB19) -> 0.076923077 | AF6: Part 1: General portfolio details | AH6: Response | AK6: Progress | AL6: =COUNTA(AH7:AL19)/ROWS(AH7:AL19) -> 0.076923077 | AP6: Part 1: General portfolio details | AR6: Response | AU6: Progress | AV6: =COUNTA(AR7:AV19)/ROWS(AR7:AV19) -> 0.076923077 | AZ6: Part 1: General portfolio details | BB6: Response | BE6: Progress | BF6: =COUNTA(BB7:BF19)/ROWS(BB7:BF19) -> 0.076923077 | BJ6: Part 1: General portfolio details | BL6: Response | BO6: Progress | BP6: =COUNTA(BL7:BP19)/ROWS(BL7:BP19) -> 0.076923077 | BT6: Part 1: General portfolio details | BV6: Response | BY6: Progress | BZ6: =COUNTA(BV7:BZ19)/ROWS(BV7:BZ19) -> 0.076923077 | CD6: Part 1: General portfolio details | CF6: Response | CI6: Progress | CJ6: =COUNTA(CF7:CJ19)/ROWS(CF7:CJ19) -> 0.076923077 | CN6: Part 1: General portfolio details | CP6: Response | CS6: Progress | CT6: =COUNTA(CP7:CT19)/ROWS(CP7:CT19) -> 0.076923077
B7: 1 | C7: Proposed managed portfolio name | D7: Aurora Growth Managed Portfolio | L7: 1 | M7: Proposed managed portfolio name | N7: Aurora Defensive Managed Portfolio | V7: 1 | W7: Proposed managed portfolio name | X7: ='Page Two - IM Info contd'!#REF! -> #REF! | AF7: 1 | AG7: Proposed managed portfolio name | AH7: ='Page Two - IM Info contd'!#REF! -> #REF! | AP7: 1 | AQ7: Proposed managed portfolio name | AR7: ='Page Two - IM Info contd'!#REF! -> #REF! | AZ7: 1 | BA7: Proposed managed portfolio name | BB7: ='Page Two - IM Info contd'!#REF! -> #REF! | BJ7: 1 | BK7: Proposed managed portfolio name | BL7: ='Page Two - IM Info contd'!#REF! -> #REF! | BT7: 1 | BU7: Proposed managed portfolio name | BV7: ='Page Two - IM Info contd'!#REF! -> #REF! | CD7: 1 | CE7: Proposed managed portfolio name | CF7: ='Page Two - IM Info contd'!#REF! -> #REF! | CN7: 1 | CO7: Proposed managed portfolio name | CP7: ='Page Two - IM Info contd'!#REF! -> #REF!
B8: 2 | C8: Proposed Asset Class | D8: Diversified | L8: 2 | M8: Proposed Asset Class | N8: Diversified | V8: 2 | W8: Proposed Asset Class | AF8: 2 | AG8: Proposed Asset Class | AP8: 2 | AQ8: Proposed Asset Class | AZ8: 2 | BA8: Proposed Asset Class | BJ8: 2 | BK8: Proposed Asset Class | BT8: 2 | BU8: Proposed Asset Class | CD8: 2 | CE8: Proposed Asset Class | CN8: 2 | CO8: Proposed Asset Class
B9: 3 | C9: Portfolio type | D9: Diversified | L9: 3 | M9: Portfolio type | N9: Diversified | V9: 3 | W9: Portfolio type | AF9: 3 | AG9: Portfolio type | AP9: 3 | AQ9: Portfolio type | AZ9: 3 | BA9: Portfolio type | BJ9: 3 | BK9: Portfolio type | BT9: 3 | BU9: Portfolio type | CD9: 3 | CE9: Portfolio type | CN9: 3 | CO9: Portfolio type
B10: 4 | C10: Investment style | D10: Active & Index | L10: 4 | M10: Investment style | N10: Active & Index | V10: 4 | W10: Investment style | AF10: 4 | AG10: Investment style | AP10: 4 | AQ10: Investment style | AZ10: 4 | BA10: Investment style | BJ10: 4 | BK10: Investment style | BT10: 4 | BU10: Investment style | CD10: 4 | CE10: Investment style | CN10: 4 | CO10: Investment style
B11: 5 | C11: Investment universe | D11: Managed funds and ETFs | L11: 5 | M11: Investment universe | N11: Managed funds and ETFs | V11: 5 | W11: Investment universe | AF11: 5 | AG11: Investment universe | AP11: 5 | AQ11: Investment universe | AZ11: 5 | BA11: Investment universe | BJ11: 5 | BK11: Investment universe | BT11: 5 | BU11: Investment universe | CD11: 5 | CE11: Investment universe | CN11: 5 | CO11: Investment universe
B12: 6 | C12: Standard Risk Measure (SRM) as per FSC guidance paper | D12: 6 | L12: 6 | M12: Standard Risk Measure (SRM) as per FSC guidance paper | N12: 3 | V12: 6 | W12: Standard Risk Measure (SRM) as per FSC guidance paper | AF12: 6 | AG12: Standard Risk Measure (SRM) as per FSC guidance paper | AP12: 6 | AQ12: Standard Risk Measure (SRM) as per FSC guidance paper | AZ12: 6 | BA12: Standard Risk Measure (SRM) as per FSC guidance paper | BJ12: 6 | BK12: Standard Risk Measure (SRM) as per FSC guidance paper | BT12: 6 | BU12: Standard Risk Measure (SRM) as per FSC guidance paper | CD12: 6 | CE12: Standard Risk Measure (SRM) as per FSC guidance paper | CN12: 6 | CO12: Standard Risk Measure (SRM) as per FSC guidance paper
B13: 7 | C13: Describe the investment objective of the portfolio starting with "Aims to deliver…" | D13: Aims to achieve a return in excess of CPI + 3.75% p.a. and outperform the Benchmark over a rolling 10 year period, net of indirect fees. | L13: 7 | M13: Describe the investment objective of the portfolio starting with "Aims to deliver…" | N13: Aims to achieve a return in excess of CPI + 0.5% p.a. and outperform the Benchmark over a rolling 2 year period, net of indirect fees. | V13: 7 | W13: Describe the investment objective of the portfolio starting with "Aims to deliver…" | AF13: 7 | AG13: Describe the investment objective of the portfolio starting with "Aims to deliver…" | AP13: 7 | AQ13: Describe the investment objective of the portfolio starting with "Aims to deliver…" | AZ13: 7 | BA13: Describe the investment objective of the portfolio starting with "Aims to deliver…" | BJ13: 7 | BK13: Describe the investment objective of the portfolio starting with "Aims to deliver…" | BT13: 7 | BU13: Describe the investment objective of the portfolio starting with "Aims to deliver…" | CD13: 7 | CE13: Describe the investment objective of the portfolio starting with "Aims to deliver…" | CN13: 7 | CO13: Describe the investment objective of the portfolio starting with "Aims to deliver…"
B14: 8 | C14: Managed portfolio benchmark (include one for each of the below if applicable; note composite benchmarks are not accepted) - Declared benchmark for Disclosure - Portfolio performance | D14: Morningstar AUS Agg Tgt Alloc NR AUD | L14: 8 | M14: Managed portfolio benchmark (include one for each of the below if applicable; note composite benchmarks are not accepted) - Declared benchmark for Disclosure - Portfolio performance | N14: Morningstar AUS Con Tgt Alloc NR AUD | V14: 8 | W14: Managed portfolio benchmark (include one for each of the below if applicable; note composite benchmarks are not accepted) - Declared benchmark for Disclosure - Portfolio performance | AF14: 8 | AG14: Managed portfolio benchmark (include one for each of the below if applicable; note composite benchmarks are not accepted) - Declared benchmark for Disclosure - Portfolio performance | AP14: 8 | AQ14: Managed portfolio benchmark (include one for each of the below if applicable; note composite benchmarks are not accepted) - Declared benchmark for Disclosure - Portfolio performance | AZ14: 8 | BA14: Managed portfolio benchmark (include one for each of the below if applicable; note composite benchmarks are not accepted) - Declared benchmark for Disclosure - Portfolio performance | BJ14: 8 | BK14: Managed portfolio benchmark (include one for each of the below if applicable; note composite benchmarks are not accepted) - Declared benchmark for Disclosure - Portfolio performance | BT14: 8 | BU14: Managed portfolio benchmark (include one for each of the below if applicable; note composite benchmarks are not accepted) - Declared benchmark for Disclosure - Portfolio performance | CD14: 8 | CE14: Managed portfolio benchmark (include one for each of the below if applicable; note composite benchmarks are not accepted) - Declared benchmark for Disclosure - Portfolio performance | CN14: 8 | CO14: Managed portfolio benchmark (include one for each of the below if applicable; note composite benchmarks are not accepted) - Declared benchmark for Disclosure - Portfolio performance
B15: =B14+1 -> 9 | C15: Income Target (only applicable for Income/Retirement strategies) | D15: N/A | L15: =L14+1 -> 9 | M15: Income Target (only applicable for Income/Retirement strategies) | N15: N/A | V15: =V14+1 -> 9 | W15: Income Target (only applicable for Income/Retirement strategies) | AF15: =AF14+1 -> 9 | AG15: Income Target (only applicable for Income/Retirement strategies) | AP15: =AP14+1 -> 9 | AQ15: Income Target (only applicable for Income/Retirement strategies) | AZ15: =AZ14+1 -> 9 | BA15: Income Target (only applicable for Income/Retirement strategies) | BJ15: =BJ14+1 -> 9 | BK15: Income Target (only applicable for Income/Retirement strategies) | BT15: =BT14+1 -> 9 | BU15: Income Target (only applicable for Income/Retirement strategies) | CD15: =CD14+1 -> 9 | CE15: Income Target (only applicable for Income/Retirement strategies) | CN15: =CN14+1 -> 9 | CO15: Income Target (only applicable for Income/Retirement strategies)
B16: =B15+1 -> 10 | C16: Target investors suitable for the portfolio "Designed for investors who seek a…" | D16: Designed for investors with a minimum 10 year timeframe, who are comfortable with high investment risk, and/or require high returns to meet their long term objectives. | L16: =L15+1 -> 10 | M16: Target investors suitable for the portfolio "Designed for investors who seek a…" | N16: Designed for investors with a minimum 2 year timeframe, who have a low tolerance to investment risk, and/or require low returns to meet their objectives | V16: =V15+1 -> 10 | W16: Target investors suitable for the portfolio "Designed for investors who seek a…" | AF16: =AF15+1 -> 10 | AG16: Target investors suitable for the portfolio "Designed for investors who seek a…" | AP16: =AP15+1 -> 10 | AQ16: Target investors suitable for the portfolio "Designed for investors who seek a…" | AZ16: =AZ15+1 -> 10 | BA16: Target investors suitable for the portfolio "Designed for investors who seek a…" | BJ16: =BJ15+1 -> 10 | BK16: Target investors suitable for the portfolio "Designed for investors who seek a…" | BT16: =BT15+1 -> 10 | BU16: Target investors suitable for the portfolio "Designed for investors who seek a…" | CD16: =CD15+1 -> 10 | CE16: Target investors suitable for the portfolio "Designed for investors who seek a…" | CN16: =CN15+1 -> 10 | CO16: Target investors suitable for the portfolio "Designed for investors who seek a…"
B17: =B16+1 -> 11 | C17: Minimum investment horizon | D17: 10 years plus | L17: =L16+1 -> 11 | M17: Minimum investment horizon | N17: 2 years plus | V17: =V16+1 -> 11 | W17: Minimum investment horizon | AF17: =AF16+1 -> 11 | AG17: Minimum investment horizon | AP17: =AP16+1 -> 11 | AQ17: Minimum investment horizon | AZ17: =AZ16+1 -> 11 | BA17: Minimum investment horizon | BJ17: =BJ16+1 -> 11 | BK17: Minimum investment horizon | BT17: =BT16+1 -> 11 | BU17: Minimum investment horizon | CD17: =CD16+1 -> 11 | CE17: Minimum investment horizon | CN17: =CN16+1 -> 11 | CO17: Minimum investment horizon
B18: =B17+1 -> 12 | C18: Probability of achieving portfolio objectives | D18: 0.6058 | L18: =L17+1 -> 12 | M18: Probability of achieving portfolio objectives | N18: 0.797 | V18: =V17+1 -> 12 | W18: Probability of achieving portfolio objectives | AF18: =AF17+1 -> 12 | AG18: Probability of achieving portfolio objectives | AP18: =AP17+1 -> 12 | AQ18: Probability of achieving portfolio objectives | AZ18: =AZ17+1 -> 12 | BA18: Probability of achieving portfolio objectives | BJ18: =BJ17+1 -> 12 | BK18: Probability of achieving portfolio objectives | BT18: =BT17+1 -> 12 | BU18: Probability of achieving portfolio objectives | CD18: =CD17+1 -> 12 | CE18: Probability of achieving portfolio objectives | CN18: =CN17+1 -> 12 | CO18: Probability of achieving portfolio objectives
B19: =B18+1 -> 13 | C19: Describe the investment strategy and approach for this portfolio - Include ESG information if applicable | D19: The portfolio is actively managed within allowable ranges and contains exposure to approximately 2% of income assets (cash and fixed interest) and 98% of growth assets (shares, property, infrastructure and alternatives), depending on market conditions. Over the medium term the portfolio manager may adjust the portfolio, within allowable ranges, in response to evolving market conditions, economic indicators and valuation signals. The aim is to enhance returns or manage risk by taking into account cyclical trends rather than relying on static long-term assumptions. | L19: =L18+1 -> 13 | M19: Describe the investment strategy and approach for this portfolio - Include ESG information if applicable | N19: The portfolio is actively managed within allowable ranges and contains exposure to approximately 100% of income assets (cash and fixed interest) and 0% of growth assets (shares, property, infrastructure and alternatives), depending on market conditions. Over the medium term the portfolio manager may adjust the portfolio, within allowable ranges, in response to evolving market conditions, economic indicators and valuation signals. The aim is to enhance returns or manage risk by taking into account cyclical trends rather than relying on static long-term assumptions. | V19: =V18+1 -> 13 | W19: Describe the investment strategy and approach for this portfolio - Include ESG information if applicable | AF19: =AF18+1 -> 13 | AG19: Describe the investment strategy and approach for this portfolio - Include ESG information if applicable | AP19: =AP18+1 -> 13 | AQ19: Describe the investment strategy and approach for this portfolio - Include ESG information if applicable | AZ19: =AZ18+1 -> 13 | BA19: Describe the investment strategy and approach for this portfolio - Include ESG information if applicable | BJ19: =BJ18+1 -> 13 | BK19: Describe the investment strategy and approach for this portfolio - Include ESG information if applicable | BT19: =BT18+1 -> 13 | BU19: Describe the investment strategy and approach for this portfolio - Include ESG information if applicable | CD19: =CD18+1 -> 13 | CE19: Describe the investment strategy and approach for this portfolio - Include ESG information if applicable | CN19: =CN18+1 -> 13 | CO19: Describe the investment strategy and approach for this portfolio - Include ESG information if applicable
B21: Part 2: Equivalent strategies - Managed fund/SMA/Model (if applicable) | D21: Response | G21: Progress | H21: =COUNTA(D22:H29)/ROWS(D22:H29) -> 1 | L21: Part 2: Equivalent strategies - Managed fund/SMA/Model (if applicable) | N21: Response | Q21: Progress | R21: =COUNTA(N22:R29)/ROWS(N22:R29) -> 1 | V21: Part 2: Equivalent strategies - Managed fund/SMA/Model (if applicable) | X21: Response | AA21: Progress | AB21: =COUNTA(X22:AB29)/ROWS(X22:AB29) -> 0 | AF21: Part 2: Equivalent strategies - Managed fund/SMA/Model (if applicable) | AH21: Response | AK21: Progress | AL21: =COUNTA(AH22:AL29)/ROWS(AH22:AL29) -> 0 | AP21: Part 2: Equivalent strategies - Managed fund/SMA/Model (if applicable) | AR21: Response | AU21: Progress | AV21: =COUNTA(AR22:AV29)/ROWS(AR22:AV29) -> 0 | AZ21: Part 2: Equivalent strategies - Managed fund/SMA/Model (if applicable) | BB21: Response | BE21: Progress | BF21: =COUNTA(BB22:BF29)/ROWS(BB22:BF29) -> 0 | BJ21: Part 2: Equivalent strategies - Managed fund/SMA/Model (if applicable) | BL21: Response | BO21: Progress | BP21: =COUNTA(BL22:BP29)/ROWS(BL22:BP29) -> 0 | BT21: Part 2: Equivalent strategies - Managed fund/SMA/Model (if applicable) | BV21: Response | BY21: Progress | BZ21: =COUNTA(BV22:BZ29)/ROWS(BV22:BZ29) -> 0 | CD21: Part 2: Equivalent strategies - Managed fund/SMA/Model (if applicable) | CF21: Response | CI21: Progress | CJ21: =COUNTA(CF22:CJ29)/ROWS(CF22:CJ29) -> 0 | CN21: Part 2: Equivalent strategies - Managed fund/SMA/Model (if applicable) | CP21: Response | CS21: Progress | CT21: =COUNTA(CP22:CT29)/ROWS(CP22:CT29) -> 0
B22: 1 | C22: Is the portfolio based on an equivalent existing strategy that has a track record? | D22: No | L22: 1 | M22: Is the portfolio based on an equivalent existing strategy that has a track record? | N22: No | V22: 1 | W22: Is the portfolio based on an equivalent existing strategy that has a track record? | AF22: 1 | AG22: Is the portfolio based on an equivalent existing strategy that has a track record? | AP22: 1 | AQ22: Is the portfolio based on an equivalent existing strategy that has a track record? | AZ22: 1 | BA22: Is the portfolio based on an equivalent existing strategy that has a track record? | BJ22: 1 | BK22: Is the portfolio based on an equivalent existing strategy that has a track record? | BT22: 1 | BU22: Is the portfolio based on an equivalent existing strategy that has a track record? | CD22: 1 | CE22: Is the portfolio based on an equivalent existing strategy that has a track record? | CN22: 1 | CO22: Is the portfolio based on an equivalent existing strategy that has a track record?
B23: 2 | C23: If yes, please provide the name of the equivalent strategy | D23: N/A | L23: 2 | M23: If yes, please provide the name of the equivalent strategy | N23: N/A | V23: 2 | W23: If yes, please provide the name of the equivalent strategy | AF23: 2 | AG23: If yes, please provide the name of the equivalent strategy | AP23: 2 | AQ23: If yes, please provide the name of the equivalent strategy | AZ23: 2 | BA23: If yes, please provide the name of the equivalent strategy | BJ23: 2 | BK23: If yes, please provide the name of the equivalent strategy | BT23: 2 | BU23: If yes, please provide the name of the equivalent strategy | CD23: 2 | CE23: If yes, please provide the name of the equivalent strategy | CN23: 2 | CO23: If yes, please provide the name of the equivalent strategy
B24: 3 | C24: Provide the equivalent strategy APIR code (if applicable) | D24: N/A | L24: 3 | M24: Provide the equivalent strategy APIR code (if applicable) | N24: N/A | V24: 3 | W24: Provide the equivalent strategy APIR code (if applicable) | AF24: 3 | AG24: Provide the equivalent strategy APIR code (if applicable) | AP24: 3 | AQ24: Provide the equivalent strategy APIR code (if applicable) | AZ24: 3 | BA24: Provide the equivalent strategy APIR code (if applicable) | BJ24: 3 | BK24: Provide the equivalent strategy APIR code (if applicable) | BT24: 3 | BU24: Provide the equivalent strategy APIR code (if applicable) | CD24: 3 | CE24: Provide the equivalent strategy APIR code (if applicable) | CN24: 3 | CO24: Provide the equivalent strategy APIR code (if applicable)
B25: 4 | C25: Explain any actual or likely differences between the portfolio and the equivalent strategy? | D25: N/A | L25: 4 | M25: Explain any actual or likely differences between the portfolio and the equivalent strategy? | N25: N/A | V25: 4 | W25: Explain any actual or likely differences between the portfolio and the equivalent strategy? | AF25: 4 | AG25: Explain any actual or likely differences between the portfolio and the equivalent strategy? | AP25: 4 | AQ25: Explain any actual or likely differences between the portfolio and the equivalent strategy? | AZ25: 4 | BA25: Explain any actual or likely differences between the portfolio and the equivalent strategy? | BJ25: 4 | BK25: Explain any actual or likely differences between the portfolio and the equivalent strategy? | BT25: 4 | BU25: Explain any actual or likely differences between the portfolio and the equivalent strategy? | CD25: 4 | CE25: Explain any actual or likely differences between the portfolio and the equivalent strategy? | CN25: 4 | CO25: Explain any actual or likely differences between the portfolio and the equivalent strategy?
B26: 5 | C26: How does you approach any potential conflicts arising as a result of running a similar strategy across different structures? E.g. timing of trades and the potential to 'front run' | D26: N/A | L26: 5 | M26: How does you approach any potential conflicts arising as a result of running a similar strategy across different structures? E.g. timing of trades and the potential to 'front run' | N26: N/A | V26: 5 | W26: How does you approach any potential conflicts arising as a result of running a similar strategy across different structures? E.g. timing of trades and the potential to 'front run' | AF26: 5 | AG26: How does you approach any potential conflicts arising as a result of running a similar strategy across different structures? E.g. timing of trades and the potential to 'front run' | AP26: 5 | AQ26: How does you approach any potential conflicts arising as a result of running a similar strategy across different structures? E.g. timing of trades and the potential to 'front run' | AZ26: 5 | BA26: How does you approach any potential conflicts arising as a result of running a similar strategy across different structures? E.g. timing of trades and the potential to 'front run' | BJ26: 5 | BK26: How does you approach any potential conflicts arising as a result of running a similar strategy across different structures? E.g. timing of trades and the potential to 'front run' | BT26: 5 | BU26: How does you approach any potential conflicts arising as a result of running a similar strategy across different structures? E.g. timing of trades and the potential to 'front run' | CD26: 5 | CE26: How does you approach any potential conflicts arising as a result of running a similar strategy across different structures? E.g. timing of trades and the potential to 'front run' | CN26: 5 | CO26: How does you approach any potential conflicts arising as a result of running a similar strategy across different structures? E.g. timing of trades and the potential to 'front run'
B27: 6 | C27: Provide the monthly Managed Portfolio performance (net of fees) | D27: N/A | L27: 6 | M27: Provide the monthly Managed Portfolio performance (net of fees) | N27: N/A | V27: 6 | W27: Provide the monthly Managed Portfolio performance (net of fees) | AF27: 6 | AG27: Provide the monthly Managed Portfolio performance (net of fees) | AP27: 6 | AQ27: Provide the monthly Managed Portfolio performance (net of fees) | AZ27: 6 | BA27: Provide the monthly Managed Portfolio performance (net of fees) | BJ27: 6 | BK27: Provide the monthly Managed Portfolio performance (net of fees) | BT27: 6 | BU27: Provide the monthly Managed Portfolio performance (net of fees) | CD27: 6 | CE27: Provide the monthly Managed Portfolio performance (net of fees) | CN27: 6 | CO27: Provide the monthly Managed Portfolio performance (net of fees)
B28: 7 | C28: Provide the monthly Implemented Portfolio performance of the portfolio on a pre existing platform | D28: N/A | L28: 7 | M28: Provide the monthly Implemented Portfolio performance of the portfolio on a pre existing platform | N28: N/A | V28: 7 | W28: Provide the monthly Implemented Portfolio performance of the portfolio on a pre existing platform | AF28: 7 | AG28: Provide the monthly Implemented Portfolio performance of the portfolio on a pre existing platform | AP28: 7 | AQ28: Provide the monthly Implemented Portfolio performance of the portfolio on a pre existing platform | AZ28: 7 | BA28: Provide the monthly Implemented Portfolio performance of the portfolio on a pre existing platform | BJ28: 7 | BK28: Provide the monthly Implemented Portfolio performance of the portfolio on a pre existing platform | BT28: 7 | BU28: Provide the monthly Implemented Portfolio performance of the portfolio on a pre existing platform | CD28: 7 | CE28: Provide the monthly Implemented Portfolio performance of the portfolio on a pre existing platform | CN28: 7 | CO28: Provide the monthly Implemented Portfolio performance of the portfolio on a pre existing platform
B29: 8 | C29: What is the expected stock holdings (MIS vs managed portfolio) overlap with any of your funds? | D29: N/A | L29: 8 | M29: What is the expected stock holdings (MIS vs managed portfolio) overlap with any of your funds? | N29: N/A | V29: 8 | W29: What is the expected stock holdings (MIS vs managed portfolio) overlap with any of your funds? | AF29: 8 | AG29: What is the expected stock holdings (MIS vs managed portfolio) overlap with any of your funds? | AP29: 8 | AQ29: What is the expected stock holdings (MIS vs managed portfolio) overlap with any of your funds? | AZ29: 8 | BA29: What is the expected stock holdings (MIS vs managed portfolio) overlap with any of your funds? | BJ29: 8 | BK29: What is the expected stock holdings (MIS vs managed portfolio) overlap with any of your funds? | BT29: 8 | BU29: What is the expected stock holdings (MIS vs managed portfolio) overlap with any of your funds? | CD29: 8 | CE29: What is the expected stock holdings (MIS vs managed portfolio) overlap with any of your funds? | CN29: 8 | CO29: What is the expected stock holdings (MIS vs managed portfolio) overlap with any of your funds?
B31: Part 3: Portfolio management information | D31: Response | G31: Progress | H31: =COUNTA(D32:H40)/ROWS(D32:H40) -> 1 | L31: Part 3: Portfolio management information | N31: Response | Q31: Progress | R31: =COUNTA(N32:R40)/ROWS(N32:R40) -> 1 | V31: Part 3: Portfolio management information | X31: Response | AA31: Progress | AB31: =COUNTA(X32:AB40)/ROWS(X32:AB40) -> 0 | AF31: Part 3: Portfolio management information | AH31: Response | AK31: Progress | AL31: =COUNTA(AH32:AL40)/ROWS(AH32:AL40) -> 0 | AP31: Part 3: Portfolio management information | AR31: Response | AU31: Progress | AV31: =COUNTA(AR32:AV40)/ROWS(AR32:AV40) -> 0 | AZ31: Part 3: Portfolio management information | BB31: Response | BE31: Progress | BF31: =COUNTA(BB32:BF40)/ROWS(BB32:BF40) -> 0 | BJ31: Part 3: Portfolio management information | BL31: Response | BO31: Progress | BP31: =COUNTA(BL32:BP40)/ROWS(BL32:BP40) -> 0 | BT31: Part 3: Portfolio management information | BV31: Response | BY31: Progress | BZ31: =COUNTA(BV32:BZ40)/ROWS(BV32:BZ40) -> 0 | CD31: Part 3: Portfolio management information | CF31: Response | CI31: Progress | CJ31: =COUNTA(CF32:CJ40)/ROWS(CF32:CJ40) -> 0 | CN31: Part 3: Portfolio management information | CP31: Response | CS31: Progress | CT31: =COUNTA(CP32:CT40)/ROWS(CP32:CT40) -> 0
B32: 1 | C32: What is the minimum number of investment options held in the portfolio? (please clarify the asset category of investment options) | D32: 10 | L32: 1 | M32: What is the minimum number of investment options held in the portfolio? (please clarify the asset category of investment options) | N32: 10 | V32: 1 | W32: What is the minimum number of investment options held in the portfolio? (please clarify the asset category of investment options) | AF32: 1 | AG32: What is the minimum number of investment options held in the portfolio? (please clarify the asset category of investment options) | AP32: 1 | AQ32: What is the minimum number of investment options held in the portfolio? (please clarify the asset category of investment options) | AZ32: 1 | BA32: What is the minimum number of investment options held in the portfolio? (please clarify the asset category of investment options) | BJ32: 1 | BK32: What is the minimum number of investment options held in the portfolio? (please clarify the asset category of investment options) | BT32: 1 | BU32: What is the minimum number of investment options held in the portfolio? (please clarify the asset category of investment options) | CD32: 1 | CE32: What is the minimum number of investment options held in the portfolio? (please clarify the asset category of investment options) | CN32: 1 | CO32: What is the minimum number of investment options held in the portfolio? (please clarify the asset category of investment options)
B33: 2 | C33: What is the maximum number of investment options held in the portfolio? (please clarify the asset category of investment options) | D33: 30 | L33: 2 | M33: What is the maximum number of investment options held in the portfolio? (please clarify the asset category of investment options) | N33: 30 | V33: 2 | W33: What is the maximum number of investment options held in the portfolio? (please clarify the asset category of investment options) | AF33: 2 | AG33: What is the maximum number of investment options held in the portfolio? (please clarify the asset category of investment options) | AP33: 2 | AQ33: What is the maximum number of investment options held in the portfolio? (please clarify the asset category of investment options) | AZ33: 2 | BA33: What is the maximum number of investment options held in the portfolio? (please clarify the asset category of investment options) | BJ33: 2 | BK33: What is the maximum number of investment options held in the portfolio? (please clarify the asset category of investment options) | BT33: 2 | BU33: What is the maximum number of investment options held in the portfolio? (please clarify the asset category of investment options) | CD33: 2 | CE33: What is the maximum number of investment options held in the portfolio? (please clarify the asset category of investment options) | CN33: 2 | CO33: What is the maximum number of investment options held in the portfolio? (please clarify the asset category of investment options)
B34: 3 | C34: What is the minimum absolute single asset position? (%) | D34: 0.01 | L34: 3 | M34: What is the minimum absolute single asset position? (%) | N34: 0.01 | V34: 3 | W34: What is the minimum absolute single asset position? (%) | AF34: 3 | AG34: What is the minimum absolute single asset position? (%) | AP34: 3 | AQ34: What is the minimum absolute single asset position? (%) | AZ34: 3 | BA34: What is the minimum absolute single asset position? (%) | BJ34: 3 | BK34: What is the minimum absolute single asset position? (%) | BT34: 3 | BU34: What is the minimum absolute single asset position? (%) | CD34: 3 | CE34: What is the minimum absolute single asset position? (%) | CN34: 3 | CO34: What is the minimum absolute single asset position? (%)
B35: 4 | C35: What is the maximum absolute single asset position? (%) | D35: 0.3 | L35: 4 | M35: What is the maximum absolute single asset position? (%) | N35: 0.3 | V35: 4 | W35: What is the maximum absolute single asset position? (%) | AF35: 4 | AG35: What is the maximum absolute single asset position? (%) | AP35: 4 | AQ35: What is the maximum absolute single asset position? (%) | AZ35: 4 | BA35: What is the maximum absolute single asset position? (%) | BJ35: 4 | BK35: What is the maximum absolute single asset position? (%) | BT35: 4 | BU35: What is the maximum absolute single asset position? (%) | CD35: 4 | CE35: What is the maximum absolute single asset position? (%) | CN35: 4 | CO35: What is the maximum absolute single asset position? (%)
B36: 5 | C36: What is the minimum single asset position for any new asset? (%) | D36: 0.01 | L36: 5 | M36: What is the minimum single asset position for any new asset? (%) | N36: 0.01 | V36: 5 | W36: What is the minimum single asset position for any new asset? (%) | AF36: 5 | AG36: What is the minimum single asset position for any new asset? (%) | AP36: 5 | AQ36: What is the minimum single asset position for any new asset? (%) | AZ36: 5 | BA36: What is the minimum single asset position for any new asset? (%) | BJ36: 5 | BK36: What is the minimum single asset position for any new asset? (%) | BT36: 5 | BU36: What is the minimum single asset position for any new asset? (%) | CD36: 5 | CE36: What is the minimum single asset position for any new asset? (%) | CN36: 5 | CO36: What is the minimum single asset position for any new asset? (%)
B37: 6 | C37: Target volatility (or other risk target TE, VaR, CVaR) | D37: N/A | L37: 6 | M37: Target volatility (or other risk target TE, VaR, CVaR) | N37: N/A | V37: 6 | W37: Target volatility (or other risk target TE, VaR, CVaR) | AF37: 6 | AG37: Target volatility (or other risk target TE, VaR, CVaR) | AP37: 6 | AQ37: Target volatility (or other risk target TE, VaR, CVaR) | AZ37: 6 | BA37: Target volatility (or other risk target TE, VaR, CVaR) | BJ37: 6 | BK37: Target volatility (or other risk target TE, VaR, CVaR) | BT37: 6 | BU37: Target volatility (or other risk target TE, VaR, CVaR) | CD37: 6 | CE37: Target volatility (or other risk target TE, VaR, CVaR) | CN37: 6 | CO37: Target volatility (or other risk target TE, VaR, CVaR)
B38: 7 | C38: Will income be reinvested or paid to the platform cash account by default? | D38: Reinvested | L38: 7 | M38: Will income be reinvested or paid to the platform cash account by default? | N38: Reinvested | V38: 7 | W38: Will income be reinvested or paid to the platform cash account by default? | AF38: 7 | AG38: Will income be reinvested or paid to the platform cash account by default? | AP38: 7 | AQ38: Will income be reinvested or paid to the platform cash account by default? | AZ38: 7 | BA38: Will income be reinvested or paid to the platform cash account by default? | BJ38: 7 | BK38: Will income be reinvested or paid to the platform cash account by default? | BT38: 7 | BU38: Will income be reinvested or paid to the platform cash account by default? | CD38: 7 | CE38: Will income be reinvested or paid to the platform cash account by default? | CN38: 7 | CO38: Will income be reinvested or paid to the platform cash account by default?
B39: 8 | C39: Minimum Cash buffer? (1% minimum required) | D39: 0.01 | L39: 8 | M39: Minimum Cash buffer? (1% minimum required) | N39: 0.01 | V39: 8 | W39: Minimum Cash buffer? (1% minimum required) | AF39: 8 | AG39: Minimum Cash buffer? (1% minimum required) | AP39: 8 | AQ39: Minimum Cash buffer? (1% minimum required) | AZ39: 8 | BA39: Minimum Cash buffer? (1% minimum required) | BJ39: 8 | BK39: Minimum Cash buffer? (1% minimum required) | BT39: 8 | BU39: Minimum Cash buffer? (1% minimum required) | CD39: 8 | CE39: Minimum Cash buffer? (1% minimum required) | CN39: 8 | CO39: Minimum Cash buffer? (1% minimum required)
B40: 9 | C40: Is the trading preference active or rebalance? | D40: Active | L40: 9 | M40: Is the trading preference active or rebalance? | N40: Active | V40: 9 | W40: Is the trading preference active or rebalance? | AF40: 9 | AG40: Is the trading preference active or rebalance? | AP40: 9 | AQ40: Is the trading preference active or rebalance? | AZ40: 9 | BA40: Is the trading preference active or rebalance? | BJ40: 9 | BK40: Is the trading preference active or rebalance? | BT40: 9 | BU40: Is the trading preference active or rebalance? | CD40: 9 | CE40: Is the trading preference active or rebalance? | CN40: 9 | CO40: Is the trading preference active or rebalance?
B41: Portfolio management - Listed Assets ONLY | D41: Response | L41: Portfolio management - Listed Assets ONLY | N41: Response | V41: Portfolio management - Listed Assets ONLY | X41: Response | AF41: Portfolio management - Listed Assets ONLY | AH41: Response | AP41: Portfolio management - Listed Assets ONLY | AR41: Response | AZ41: Portfolio management - Listed Assets ONLY | BB41: Response | BJ41: Portfolio management - Listed Assets ONLY | BL41: Response | BT41: Portfolio management - Listed Assets ONLY | BV41: Response | CD41: Portfolio management - Listed Assets ONLY | CF41: Response | CN41: Portfolio management - Listed Assets ONLY | CP41: Response
B42: 1 | C42: Expected Turnover (p.a.) | L42: 1 | M42: Expected Turnover (p.a.) | V42: 1 | W42: Expected Turnover (p.a.) | AF42: 1 | AG42: Expected Turnover (p.a.) | AP42: 1 | AQ42: Expected Turnover (p.a.) | AZ42: 1 | BA42: Expected Turnover (p.a.) | BJ42: 1 | BK42: Expected Turnover (p.a.) | BT42: 1 | BU42: Expected Turnover (p.a.) | CD42: 1 | CE42: Expected Turnover (p.a.) | CN42: 1 | CO42: Expected Turnover (p.a.)
B43: 2 | C43: Active Stock Limits (+/- benchmark weight) | L43: 2 | M43: Active Stock Limits (+/- benchmark weight) | V43: 2 | W43: Active Stock Limits (+/- benchmark weight) | AF43: 2 | AG43: Active Stock Limits (+/- benchmark weight) | AP43: 2 | AQ43: Active Stock Limits (+/- benchmark weight) | AZ43: 2 | BA43: Active Stock Limits (+/- benchmark weight) | BJ43: 2 | BK43: Active Stock Limits (+/- benchmark weight) | BT43: 2 | BU43: Active Stock Limits (+/- benchmark weight) | CD43: 2 | CE43: Active Stock Limits (+/- benchmark weight) | CN43: 2 | CO43: Active Stock Limits (+/- benchmark weight)
B44: 3 | C44: Active GICS Sector Limits (+/- benchmark weight) | L44: 3 | M44: Active GICS Sector Limits (+/- benchmark weight) | V44: 3 | W44: Active GICS Sector Limits (+/- benchmark weight) | AF44: 3 | AG44: Active GICS Sector Limits (+/- benchmark weight) | AP44: 3 | AQ44: Active GICS Sector Limits (+/- benchmark weight) | AZ44: 3 | BA44: Active GICS Sector Limits (+/- benchmark weight) | BJ44: 3 | BK44: Active GICS Sector Limits (+/- benchmark weight) | BT44: 3 | BU44: Active GICS Sector Limits (+/- benchmark weight) | CD44: 3 | CE44: Active GICS Sector Limits (+/- benchmark weight) | CN44: 3 | CO44: Active GICS Sector Limits (+/- benchmark weight)
...

Sheet Page Five - Portfolio Snapshot
B2: MyNorth Investment Manager Onboarding Questionnaire
B3: Page Five: Portfolio Snapshot
B4: All information required
C5: PLEASE POPULATE THIS WORKSHEET FOR THE AUSTRALIAN EQUITIES PORTFOLIO ONLY
B6: Portfolio name | D6: ='Page Two - IM Info contd'!#REF! -> #REF! | J6: Contributors and Detractors | R6: Portfolio name | T6: ='Page Two - IM Info contd'!#REF! -> #REF! | Z6: Contributors and Detractors | AH6: Portfolio name | AJ6: ='Page Two - IM Info contd'!#REF! -> #REF! | AP6: Contributors and Detractors | AX6: Portfolio name | AZ6: ='Page Two - IM Info contd'!#REF! -> #REF! | BF6: Contributors and Detractors | BN6: Portfolio name | BP6: ='Page Two - IM Info contd'!#REF! -> #REF! | BV6: Contributors and Detractors | CD6: Portfolio name | CF6: ='Page Two - IM Info contd'!#REF! -> #REF! | CL6: Contributors and Detractors | CT6: Portfolio name | CV6: ='Page Two - IM Info contd'!#REF! -> #REF! | DB6: Contributors and Detractors | DJ6: Portfolio name | DL6: ='Page Two - IM Info contd'!#REF! -> #REF! | DR6: Contributors and Detractors | DZ6: Portfolio name | EB6: ='Page Two - IM Info contd'!#REF! -> #REF! | EH6: Contributors and Detractors | EP6: Portfolio name | ER6: ='Page Two - IM Info contd'!#REF! -> #REF! | EX6: Contributors and Detractors
B7: Portfolio type | D7: ='Page Four - Portfolio Details'!E81 -> 0 | R7: Portfolio type | T7: ='Page Four - Portfolio Details'!O81 -> 0 | AH7: Portfolio type | AJ7: ='Page Four - Portfolio Details'!Y81 -> 0 | AX7: Portfolio type | AZ7: ='Page Four - Portfolio Details'!AI81 -> 0 | BN7: Portfolio type | BP7: ='Page Four - Portfolio Details'!AS81 -> 0 | CD7: Portfolio type | CF7: ='Page Four - Portfolio Details'!BC81 -> 0 | CT7: Portfolio type | CV7: ='Page Four - Portfolio Details'!BM81 -> 0 | DJ7: Portfolio type | DL7: ='Page Four - Portfolio Details'!BW81 -> 0 | DZ7: Portfolio type | EB7: ='Page Four - Portfolio Details'!CG81 -> 0 | EP7: Portfolio type | ER7: ='Page Four - Portfolio Details'!CQ81 -> 0
B8: Benchmark | D8: ='Page Four - Portfolio Details'!E86 -> 0 | J8: Top 5 Contributors - 1 year | R8: Benchmark | T8: ='Page Four - Portfolio Details'!O86 -> 0 | Z8: Top 5 Contributors - 1 year | AH8: Benchmark | AJ8: ='Page Four - Portfolio Details'!Y86 -> 0 | AP8: Top 5 Contributors - 1 year | AX8: Benchmark | AZ8: ='Page Four - Portfolio Details'!AI86 -> 0 | BF8: Top 5 Contributors - 1 year | BN8: Benchmark | BP8: ='Page Four - Portfolio Details'!AS86 -> 0 | BV8: Top 5 Contributors - 1 year | CD8: Benchmark | CF8: ='Page Four - Portfolio Details'!BC86 -> 0 | CL8: Top 5 Contributors - 1 year | CT8: Benchmark | CV8: ='Page Four - Portfolio Details'!BM86 -> 0 | DB8: Top 5 Contributors - 1 year | DJ8: Benchmark | DL8: ='Page Four - Portfolio Details'!BW86 -> 0 | DR8: Top 5 Contributors - 1 year | DZ8: Benchmark | EB8: ='Page Four - Portfolio Details'!CG86 -> 0 | EH8: Top 5 Contributors - 1 year | EP8: Benchmark | ER8: ='Page Four - Portfolio Details'!CQ86 -> 0 | EX8: Top 5 Contributors - 1 year
J9: Security name | L9: Sector | M9: Relative contribution % | Z9: Security name | AB9: Sector | AC9: Relative contribution % | AP9: Security name | AR9: Sector | AS9: Relative contribution % | BF9: Security name | BH9: Sector | BI9: Relative contribution % | BV9: Security name | BX9: Sector | BY9: Relative contribution % | CL9: Security name | CN9: Sector | CO9: Relative contribution % | DB9: Security name | DD9: Sector | DE9: Relative contribution % | DR9: Security name | DT9: Sector | DU9: Relative contribution % | EH9: Security name | EJ9: Sector | EK9: Relative contribution % | EX9: Security name | EZ9: Sector | FA9: Relative contribution %
I10: 1 | Y10: 1 | AO10: 1 | BE10: 1 | BU10: 1 | CK10: 1 | DA10: 1 | DQ10: 1 | EG10: 1 | EW10: 1
B11: GICS Sector exposures | I11: 2 | R11: GICS Sector exposures | Y11: 2 | AH11: GICS Sector exposures | AO11: 2 | AX11: GICS Sector exposures | BE11: 2 | BN11: GICS Sector exposures | BU11: 2 | CD11: GICS Sector exposures | CK11: 2 | CT11: GICS Sector exposures | DA11: 2 | DJ11: GICS Sector exposures | DQ11: 2 | DZ11: GICS Sector exposures | EG11: 2 | EP11: GICS Sector exposures | EW11: 2
D12: Portfolio Weight % | E12: Index Weight % | F12: Active Weight % | I12: 3 | T12: Portfolio Weight % | U12: Index Weight % | V12: Active Weight % | Y12: 3 | AJ12: Portfolio Weight % | AK12: Index Weight % | AL12: Active Weight % | AO12: 3 | AZ12: Portfolio Weight % | BA12: Index Weight % | BB12: Active Weight % | BE12: 3 | BP12: Portfolio Weight % | BQ12: Index Weight % | BR12: Active Weight % | BU12: 3 | CF12: Portfolio Weight % | CG12: Index Weight % | CH12: Active Weight % | CK12: 3 | CV12: Portfolio Weight % | CW12: Index Weight % | CX12: Active Weight % | DA12: 3 | DL12: Portfolio Weight % | DM12: Index Weight % | DN12: Active Weight % | DQ12: 3 | EB12: Portfolio Weight % | EC12: Index Weight % | ED12: Active Weight % | EG12: 3 | ER12: Portfolio Weight % | ES12: Index Weight % | ET12: Active Weight % | EW12: 3
B13: Materials | I13: 4 | R13: Materials | Y13: 4 | AH13: Materials | AO13: 4 | AX13: Materials | BE13: 4 | BN13: Materials | BU13: 4 | CD13: Materials | CK13: 4 | CT13: Materials | DA13: 4 | DJ13: Materials | DQ13: 4 | DZ13: Materials | EG13: 4 | EP13: Materials | EW13: 4
B14: Metals and Mining | I14: 5 | R14: Metals and Mining | Y14: 5 | AH14: Metals and Mining | AO14: 5 | AX14: Metals and Mining | BE14: 5 | BN14: Metals and Mining | BU14: 5 | CD14: Metals and Mining | CK14: 5 | CT14: Metals and Mining | DA14: 5 | DJ14: Metals and Mining | DQ14: 5 | DZ14: Metals and Mining | EG14: 5 | EP14: Metals and Mining | EW14: 5
B15: Energy | R15: Energy | AH15: Energy | AX15: Energy | BN15: Energy | CD15: Energy | CT15: Energy | DJ15: Energy | DZ15: Energy | EP15: Energy
B16: Industrials | J16: Top 5 Contributors - 3 years (annualised) | R16: Industrials | Z16: Top 5 Contributors - 3 years (annualised) | AH16: Industrials | AP16: Top 5 Contributors - 3 years (annualised) | AX16: Industrials | BF16: Top 5 Contributors - 3 years (annualised) | BN16: Industrials | BV16: Top 5 Contributors - 3 years (annualised) | CD16: Industrials | CL16: Top 5 Contributors - 3 years (annualised) | CT16: Industrials | DB16: Top 5 Contributors - 3 years (annualised) | DJ16: Industrials | DR16: Top 5 Contributors - 3 years (annualised) | DZ16: Industrials | EH16: Top 5 Contributors - 3 years (annualised) | EP16: Industrials | EX16: Top 5 Contributors - 3 years (annualised)
B17: Consumer Discretionary | J17: Security name | L17: Sector | M17: Relative contribution % | R17: Consumer Discretionary | Z17: Security name | AB17: Sector | AC17: Relative contribution % | AH17: Consumer Discretionary | AP17: Security name | AR17: Sector | AS17: Relative contribution % | AX17: Consumer Discretionary | BF17: Security name | BH17: Sector | BI17: Relative contribution % | BN17: Consumer Discretionary | BV17: Security name | BX17: Sector | BY17: Relative contribution % | CD17: Consumer Discretionary | CL17: Security name | CN17: Sector | CO17: Relative contribution % | CT17: Consumer Discretionary | DB17: Security name | DD17: Sector | DE17: Relative contribution % | DJ17: Consumer Discretionary | DR17: Security name | DT17: Sector | DU17: Relative contribution % | DZ17: Consumer Discretionary | EH17: Security name | EJ17: Sector | EK17: Relative contribution % | EP17: Consumer Discretionary | EX17: Security name | EZ17: Sector | FA17: Relative contribution %
B18: Consumer Staples | I18: 1 | R18: Consumer Staples | Y18: 1 | AH18: Consumer Staples | AO18: 1 | AX18: Consumer Staples | BE18: 1 | BN18: Consumer Staples | BU18: 1 | CD18: Consumer Staples | CK18: 1 | CT18: Consumer Staples | DA18: 1 | DJ18: Consumer Staples | DQ18: 1 | DZ18: Consumer Staples | EG18: 1 | EP18: Consumer Staples | EW18: 1
B19: Health Care | I19: 2 | R19: Health Care | Y19: 2 | AH19: Health Care | AO19: 2 | AX19: Health Care | BE19: 2 | BN19: Health Care | BU19: 2 | CD19: Health Care | CK19: 2 | CT19: Health Care | DA19: 2 | DJ19: Health Care | DQ19: 2 | DZ19: Health Care | EG19: 2 | EP19: Health Care | EW19: 2
B20: Financials | I20: 3 | R20: Financials | Y20: 3 | AH20: Financials | AO20: 3 | AX20: Financials | BE20: 3 | BN20: Financials | BU20: 3 | CD20: Financials | CK20: 3 | CT20: Financials | DA20: 3 | DJ20: Financials | DQ20: 3 | DZ20: Financials | EG20: 3 | EP20: Financials | EW20: 3
