Workbook

Sheet Fee Summary
A1: IM Fee % p.a. | B1: 0.0045 | C1: 0.0045 | D1: 0.0045 | E1: 0.0045 | F1: 0.0045
A2: RE Fee % p.a. | B2: 0.0008 | C2: 0.0008 | D2: 0.0008 | E2: 0.0008 | F2: 0.0008
A3: Fee Component | B3: iShares Enhanced Strategic Conservative | C3: iShares Enhanced Strategic Moderate | D3: iShares Enhanced Strategic Balanced | E3: iShares Enhanced Strategic Growth | F3: iShares Enhanced Strategic Aggressive
A4: Investment management fees % p.a. | B4: =(B$1*(1+0.1-0.1*0.75)+B$2*(1+0.1-0.1*0.55)) | C4: =(C$1*(1+0.1-0.1*0.75)+C$2*(1+0.1-0.1*0.55)) | D4: =(D$1*(1+0.1-0.1*0.75)+D$2*(1+0.1-0.1*0.55)) | E4: =(E$1*(1+0.1-0.1*0.75)+E$2*(1+0.1-0.1*0.55)) | F4: =(F$1*(1+0.1-0.1*0.75)+F$2*(1+0.1-0.1*0.55))
A5: Rebate % p.a. | B5: =SUMPRODUCT('Portfolio Holdings'!$D$2:$D$19,'Component'!$I$2:$I$19) | C5: =SUMPRODUCT('Portfolio Holdings'!$D$20:$D$38,'Component'!$I$20:$I$38) | D5: =SUMPRODUCT('Portfolio Holdings'!$D$39:$D$57,'Component'!$I$39:$I$57) | E5: =SUMPRODUCT('Portfolio Holdings'!$D$58:$D$73,'Component'!$I$58:$I$73) | F5: =SUMPRODUCT('Portfolio Holdings'!$D$74:$D$85,'Component'!$I$74:$I$85)
A6: Estimated underlying management fees % p.a. | B6: =SUMPRODUCT('Portfolio Holdings'!$D$2:$D$19,'Component'!$C$2:$C$19)-B5 | C6: =SUMPRODUCT('Portfolio Holdings'!$D$20:$D$38,'Component'!$C$20:$C$38)-C5 | D6: =SUMPRODUCT('Portfolio Holdings'!$D$39:$D$57,'Component'!$C$39:$C$57)-D5 | E6: =SUMPRODUCT('Portfolio Holdings'!$D$58:$D$73,'Component'!$C$58:$C$73)-E5 | F6: =SUMPRODUCT('Portfolio Holdings'!$D$74:$D$85,'Component'!$C$74:$C$85)-F5
A7: Estimated managed portfolio cash investment fee % p.a. | B7: =SUMPRODUCT('Portfolio Holdings'!$D$2:$D$19,'Component'!$D$2:$D$19) | C7: =SUMPRODUCT('Portfolio Holdings'!$D$20:$D$38,'Component'!$D$20:$D$38) | D7: =SUMPRODUCT('Portfolio Holdings'!$D$39:$D$57,'Component'!$D$39:$D$57) | E7: =SUMPRODUCT('Portfolio Holdings'!$D$58:$D$73,'Component'!$D$58:$D$73) | F7: =SUMPRODUCT('Portfolio Holdings'!$D$74:$D$85,'Component'!$D$74:$D$85)
A8: Portfolio performance fee % p.a. | B8: =0 | C8: =0 | D8: =0 | E8: =0 | F8: =0
A9: Estimated underlying performance fee % p.a. | B9: =SUMPRODUCT('Portfolio Holdings'!$D$2:$D$19,'Component'!$E$2:$E$19) | C9: =SUMPRODUCT('Portfolio Holdings'!$D$20:$D$38,'Component'!$E$20:$E$38) | D9: =SUMPRODUCT('Portfolio Holdings'!$D$39:$D$57,'Component'!$E$39:$E$57) | E9: =SUMPRODUCT('Portfolio Holdings'!$D$58:$D$73,'Component'!$E$58:$E$73) | F9: =SUMPRODUCT('Portfolio Holdings'!$D$74:$D$85,'Component'!$E$74:$E$85)
A10: Estimated gross transaction costs % p.a. | B10: =SUMPRODUCT('Portfolio Holdings'!$D$2:$D$19,'Component'!$F$2:$F$19) | C10: =SUMPRODUCT('Portfolio Holdings'!$D$20:$D$38,'Component'!$F$20:$F$38) | D10: =SUMPRODUCT('Portfolio Holdings'!$D$39:$D$57,'Component'!$F$39:$F$57) | E10: =SUMPRODUCT('Portfolio Holdings'!$D$58:$D$73,'Component'!$F$58:$F$73) | F10: =SUMPRODUCT('Portfolio Holdings'!$D$74:$D$85,'Component'!$F$74:$F$85)
A11: Estimated underlying buy spread % p.a. | B11: =SUMPRODUCT('Portfolio Holdings'!$D$2:$D$19,'Component'!$G$2:$G$19) | C11: =SUMPRODUCT('Portfolio Holdings'!$D$20:$D$38,'Component'!$G$20:$G$38) | D11: =SUMPRODUCT('Portfolio Holdings'!$D$39:$D$57,'Component'!$G$39:$G$57) | E11: =SUMPRODUCT('Portfolio Holdings'!$D$58:$D$73,'Component'!$G$58:$G$73) | F11: =SUMPRODUCT('Portfolio Holdings'!$D$74:$D$85,'Component'!$G$74:$G$85)
A12: Estimated underlying sell spread % p.a. | B12: =SUMPRODUCT('Portfolio Holdings'!$D$2:$D$19,'Component'!$H$2:$H$19) | C12: =SUMPRODUCT('Portfolio Holdings'!$D$20:$D$38,'Component'!$H$20:$H$38) | D12: =SUMPRODUCT('Portfolio Holdings'!$D$39:$D$57,'Component'!$H$39:$H$57) | E12: =SUMPRODUCT('Portfolio Holdings'!$D$58:$D$73,'Component'!$H$58:$H$73) | F12: =SUMPRODUCT('Portfolio Holdings'!$D$74:$D$85,'Component'!$H$74:$H$85)

Sheet Component
A1: Unit ID | B1: Unit Name | C1: Management fees and costs % | D1: Cash investment fee % | E1: Performance fees % | F1: Gross transaction costs % | G1: Buy spread % | H1: Sell spread % | I1: Rebate % | J1: PDS URL
A2: AESG | B2: Ishares Global Aggregate Bond Esg (Aud Hedged) Etf | C2: 0.0082 | D2: 0 | E2: 0 | F2: 0 | G2: 0 | H2: 0 | I2: 0 | J2: https://www.blackrock.com/au/
A3: CASHACCT | B3: Cash Account | C3: 0 | D3: 0.014 | E3: 0 | F3: 0 | G3: 0 | H3: 0 | I3: 0
A4: EMXC | B4: Ishares Msci Emerging Markets EX China Etf | C4: 0.0017 | D4: 0 | E4: 0 | F4: 0 | G4: 0 | H4: 0 | I4: 0 | J4: https://www.blackrock.com/au/
A5: GLDN | B5: Ishares Physical Gold Etf | C5: 0.0029 | D5: 0 | E5: 0 | F5: 0 | G5: 0 | H5: 0 | I5: 0 | J5: https://www.blackrock.com/au/
A6: GLIN | B6: iShares Core FTSE Global Infrastructure (AUD Hedged) ETF | C6: 0.0077 | D6: 0 | E6: 0 | F6: 0 | G6: 0 | H6: 0 | I6: 0 | J6: https://www.blackrock.com/au/
A7: IACT | B7: Ishares U.S. Factor Rotation Active Etf | C7: 0.0031 | D7: 0 | E7: 0 | F7: 0 | G7: 0 | H7: 0 | I7: 0 | J7: https://www.blackrock.com/au/
A8: IAF | B8: Ishares Core Composite Bond Etf | C8: 0.008 | D8: 0 | E8: 0 | F8: 0 | G8: 0 | H8: 0 | I8: 0 | J8: https://www.blackrock.com/au/
A9: ICOR | B9: Ishares Core Corporate Bond Etf | C9: 0.0006 | D9: 0 | E9: 0 | F9: 0 | G9: 0 | H9: 0 | I9: 0 | J9: https://www.blackrock.com/au/
A10: IEM | B10: Ishares Msci Emerging Markets Etf | C10: 0.0022 | D10: 0 | E10: 0 | F10: 0 | G10: 0 | H10: 0 | I10: 0 | J10: https://www.blackrock.com/au/
A11: IEU | B11: Ishares Europe Etf | C11: 0.0054 | D11: 0 | E11: 0 | F11: 0 | G11: 0 | H11: 0 | I11: 0 | J11: https://www.blackrock.com/au/
A12: IGB | B12: Ishares Treasury Etf | C12: 0.0078 | D12: 0 | E12: 0 | F12: 0 | G12: 0 | H12: 0 | I12: 0 | J12: https://www.blackrock.com/au/
A13: IHHY | B13: Ishares Global High Yield Bond (Aud Hedged) Etf | C13: 0.0037 | D13: 0 | E13: 0 | F13: 0 | G13: 0 | H13: 0 | I13: 0 | J13: https://www.blackrock.com/au/
A14: IHVV | B14: Ishares S&P 500 Aud Hedged Etf | C14: 0.0046 | D14: 0 | E14: 0 | F14: 0 | G14: 0 | H14: 0 | I14: 0 | J14: https://www.blackrock.com/au/
A15: IJP | B15: Ishares Msci Japan Etf | C15: 0.0052 | D15: 0 | E15: 0 | F15: 0 | G15: 0 | H15: 0 | I15: 0 | J15: https://www.blackrock.com/au/
... A20: AESG | B20: Ishares Global Aggregate Bond Esg (Aud Hedged) Etf | C20: 0.0082 | D20: 0 | E20: 0 | F20: 0 | G20: 0 | H20: 0 | I20: 0 | J20: https://www.blackrock.com/au/
A21: CASHACCT | B21: Cash Account | C21: 0 | D21: 0.014 | E21: 0 | F21: 0 | G21: 0 | H21: 0 | I21: 0
A22: EMXC | B22: Ishares Msci Emerging Markets EX China Etf | C22: 0.0017 | D22: 0 | E22: 0 | F22: 0 | G22: 0 | H22: 0 | I22: 0 | J22: https://www.blackrock.com/au/
A23: GLDN | B23: Ishares Physical Gold Etf | C23: 0.0029 | D23: 0 | E23: 0 | F23: 0 | G23: 0 | H23: 0 | I23: 0 | J23: https://www.blackrock.com/au/
A24: GLIN | B24: iShares Core FTSE Global Infrastructure (AUD Hedged) ETF | C24: 0.0077 | D24: 0 | E24: 0 | F24: 0 | G24: 0 | H24: 0 | I24: 0 | J24: https://www.blackrock.com/au/
A25: IACT | B25: Ishares U.S. Factor Rotation Active Etf | C25: 0.0031 | D25: 0 | E25: 0 | F25: 0 | G25: 0 | H25: 0 | I25: 0 | J25: https://www.blackrock.com/au/
A26: IAF | B26: Ishares Core Composite Bond Etf | C26: 0.008 | D26: 0 | E26: 0 | F26: 0 | G26: 0 | H26: 0 | I26: 0 | J26: https://www.blackrock.com/au/
A27: ICOR | B27: Ishares Core Corporate Bond Etf | C27: 0.0006 | D27: 0 | E27: 0 | F27: 0 | G27: 0 | H27: 0 | I27: 0 | J27: https://www.blackrock.com/au/
A28: IEM | B28: Ishares Msci Emerging Markets Etf | C28: 0.0022 | D28: 0 | E28: 0 | F28: 0 | G28: 0 | H28: 0 | I28: 0 | J28: https://www.blackrock.com/au/
A29: IEU | B29: Ishares Europe Etf | C29: 0.0054 | D29: 0 | E29: 0 | F29: 0 | G29: 0 | H29: 0 | I29: 0 | J29: https://www.blackrock.com/au/
A30: IGB | B30: Ishares Treasury Etf | C30: 0.0078 | D30: 0 | E30: 0 | F30: 0 | G30: 0 | H30: 0 | I30: 0 | J30: https://www.blackrock.com/au/
A31: IHHY | B31: Ishares Global High Yield Bond (Aud Hedged) Etf | C31: 0.0037 | D31: 0 | E31: 0 | F31: 0 | G31: 0 | H31: 0 | I31: 0 | J31: https://www.blackrock.com/au/
A32: IHVV | B32: Ishares S&P 500 Aud Hedged Etf | C32: 0.0046 | D32: 0 | E32: 0 | F32: 0 | G32: 0 | H32: 0 | I32: 0 | J32: https://www.blackrock.com/au/
A33: IJP | B33: Ishares Msci Japan Etf | C33: 0.0052 | D33: 0 | E33: 0 | F33: 0 | G33: 0 | H33: 0 | I33: 0 | J33: https://www.blackrock.com/au/
... A39: AESG | B39: Ishares Global Aggregate Bond Esg (Aud Hedged) Etf | C39: 0.0082 | D39: 0 | E39: 0 | F39: 0 | G39: 0 | H39: 0 | I39: 0 | J39: https://www.blackrock.com/au/
A40: CASHACCT | B40: Cash Account | C40: 0 | D40: 0.014 | E40: 0 | F40: 0 | G40: 0 | H40: 0 | I40: 0
A41: EMXC | B41: Ishares Msci Emerging Markets EX China Etf | C41: 0.0017 | D41: 0 | E41: 0 | F41: 0 | G41: 0 | H41: 0 | I41: 0 | J41: https://www.blackrock.com/au/
A42: GLDN | B42: Ishares Physical Gold Etf | C42: 0.0029 | D42: 0 | E42: 0 | F42: 0 | G42: 0 | H42: 0 | I42: 0 | J42: https://www.blackrock.com/au/
A43: GLIN | B43: iShares Core FTSE Global Infrastructure (AUD Hedged) ETF | C43: 0.0077 | D43: 0 | E43: 0 | F43: 0 | G43: 0 | H43: 0 | I43: 0 | J43: https://www.blackrock.com/au/
A44: GLPR | B44: Ishares Ftse Gbl Property EX Aus (Aud Hedged) Etf | C44: 0.0071 | D44: 0 | E44: 0 | F44: 0 | G44: 0 | H44: 0 | I44: 0 | J44: https://www.blackrock.com/au/
A45: IACT | B45: Ishares U.S. Factor Rotation Active Etf | C45: 0.0031 | D45: 0 | E45: 0 | F45: 0 | G45: 0 | H45: 0 | I45: 0 | J45: https://www.blackrock.com/au/
A46: IAF | B46: Ishares Core Composite Bond Etf | C46: 0.008 | D46: 0 | E46: 0 | F46: 0 | G46: 0 | H46: 0 | I46: 0 | J46: https://www.blackrock.com/au/
A47: IEM | B47: Ishares Msci Emerging Markets Etf | C47: 0.0022 | D47: 0 | E47: 0 | F47: 0 | G47: 0 | H47: 0 | I47: 0 | J47: https://www.blackrock.com/au/
A48: IEU | B48: Ishares Europe Etf | C48: 0.0054 | D48: 0 | E48: 0 | F48: 0 | G48: 0 | H48: 0 | I48: 0 | J48: https://www.blackrock.com/au/
A49: IGB | B49: Ishares Treasury Etf | C49: 0.0078 | D49: 0 | E49: 0 | F49: 0 | G49: 0 | H49: 0 | I49: 0 | J49: https://www.blackrock.com/au/
...

Sheet Portfolio Holdings
A1: Portfolio ID | B1: Portfolio Name | C1: Unit ID | D1: Allocation %
A2: NTH0001 | B2: iShares Enhanced Strategic Conservative | C2: AESG | D2: 0.111
A3: NTH0001 | B3: iShares Enhanced Strategic Conservative | C3: CASHACCT | D3: 0.025
A4: NTH0001 | B4: iShares Enhanced Strategic Conservative | C4: EMXC | D4: 0.015
A5: NTH0001 | B5: iShares Enhanced Strategic Conservative | C5: GLDN | D5: 0.03
A6: NTH0001 | B6: iShares Enhanced Strategic Conservative | C6: GLIN | D6: 0.045
A7: NTH0001 | B7: iShares Enhanced Strategic Conservative | C7: IACT | D7: 0.02
A8: NTH0001 | B8: iShares Enhanced Strategic Conservative | C8: IAF | D8: 0.186
A9: NTH0001 | B9: iShares Enhanced Strategic Conservative | C9: ICOR | D9: 0.051
A10: NTH0001 | B10: iShares Enhanced Strategic Conservative | C10: IEM | D10: 0.04
A11: NTH0001 | B11: iShares Enhanced Strategic Conservative | C11: IEU | D11: 0.012
A12: NTH0001 | B12: iShares Enhanced Strategic Conservative | C12: IGB | D12: 0.045
A13: NTH0001 | B13: iShares Enhanced Strategic Conservative | C13: IHHY | D13: 0.015
... A85: NTH0005 | B85: iShares Enhanced Strategic Aggressive | C85: CASHACCT | D85: 0.02
